Workbook

Sheet churn
A1: State | B1: Account length | C1: Area code | D1: International plan | E1: Voice mail plan | F1: Number vmail messages | G1: Total day minutes | H1: Total day calls | I1: Total day charge | J1: Total eve minutes | K1: Total eve calls | L1: Total eve charge | M1: Total night minutes | N1: Total night calls | O1: Total night charge | P1: Total intl minutes | Q1: Total intl calls | R1: Total intl charge | S1: Customer service calls | T1: Churn
A2: LA | B2: 117 | C2: 408 | D2: No | E2: No | F2: 0 | G2: 184.5 | H2: 97 | I2: 31.37 | J2: 351.6 | K2: 80 | L2: 29.89 | M2: 215.8 | N2: 90 | O2: 9.71 | P2: 8.7 | Q2: 4 | R2: 2.35 | S2: 1 | T2: FALSE
A3: IN | B3: 65 | C3: 415 | D3: No | E3: No | F3: 0 | G3: 129.1 | H3: 137 | I3: 21.95 | J3: 228.5 | K3: 83 | L3: 19.42 | M3: 208.8 | N3: 111 | O3: 9.4 | P3: 12.7 | Q3: 6 | R3: 3.43 | S3: 4 | T3: TRUE
A4: NY | B4: 161 | C4: 415 | D4: No | E4: No | F4: 0 | G4: 332.9 | H4: 67 | I4: 56.59 | J4: 317.8 | K4: 97 | L4: 27.01 | M4: 160.6 | N4: 128 | O4: 7.23 | P4: 5.4 | Q4: 9 | R4: 1.46 | S4: 4 | T4: TRUE
A5: SC | B5: 111 | C5: 415 | D5: No | E5: No | F5: 0 | G5: 110.4 | H5: 103 | I5: 18.77 | J5: 137.3 | K5: 102 | L5: 11.67 | M5: 189.6 | N5: 105 | O5: 8.53 | P5: 7.7 | Q5: 6 | R5: 2.08 | S5: 2 | T5: FALSE
A6: HI | B6: 49 | C6: 510 | D6: No | E6: No | F6: 0 | G6: 119.3 | H6: 117 | I6: 20.28 | J6: 215.1 | K6: 109 | L6: 18.28 | M6: 178.7 | N6: 90 | O6: 8.04 | P6: 11.1 | Q6: 1 | R6: 3 | S6: 1 | T6: FALSE
A7: AK | B7: 36 | C7: 408 | D7: No | E7: Yes | F7: 30 | G7: 146.3 | H7: 128 | I7: 24.87 | J7: 162.5 | K7: 80 | L7: 13.81 | M7: 129.3 | N7: 109 | O7: 5.82 | P7: 14.5 | Q7: 6 | R7: 3.92 | S7: 0 | T7: FALSE
A8: MI | B8: 65 | C8: 415 | D8: No | E8: No | F8: 0 | G8: 211.3 | H8: 120 | I8: 35.92 | J8: 162.6 | K8: 122 | L8: 13.82 | M8: 134.7 | N8: 118 | O8: 6.06 | P8: 13.2 | Q8: 5 | R8: 3.56 | S8: 3 | T8: FALSE
A9: ID | B9: 119 | C9: 415 | D9: No | E9: No | F9: 0 | G9: 159.1 | H9: 114 | I9: 27.05 | J9: 231.3 | K9: 117 | L9: 19.66 | M9: 143.2 | N9: 91 | O9: 6.44 | P9: 8.8 | Q9: 3 | R9: 2.38 | S9: 5 | T9: TRUE
A10: VA | B10: 10 | C10: 408 | D10: No | E10: No | F10: 0 | G10: 186.1 | H10: 112 | I10: 31.64 | J10: 190.2 | K10: 66 | L10: 16.17 | M10: 282.8 | N10: 57 | O10: 12.73 | P10: 11.4 | Q10: 6 | R10: 3.08 | S10: 2 | T10: FALSE
A11: WI | B11: 68 | C11: 415 | D11: No | E11: No | F11: 0 | G11: 148.8 | H11: 70 | I11: 25.3 | J11: 246.5 | K11: 164 | L11: 20.95 | M11: 129.8 | N11: 103 | O11: 5.84 | P11: 12.1 | Q11: 3 | R11: 3.27 | S11: 3 | T11: FALSE
A12: MN | B12: 74 | C12: 510 | D12: No | E12: Yes | F12: 33 | G12: 193.7 | H12: 91 | I12: 32.93 | J12: 246.1 | K12: 96 | L12: 20.92 | M12: 138 | N12: 92 | O12: 6.21 | P12: 14.6 | Q12: 3 | R12: 3.94 | S12: 2 | T12: FALSE
A13: HI | B13: 85 | C13: 415 | D13: No | E13: No | F13: 0 | G13: 235.8 | H13: 109 | I13: 40.09 | J13: 157.2 | K13: 94 | L13: 13.36 | M13: 188.2 | N13: 99 | O13: 8.47 | P13: 12 | Q13: 3 | R13: 3.24 | S13: 0 | T13: FALSE
... A668: CT | B668: 184 | C668: 510 | D668: Yes | E668: No | F668: 0 | G668: 213.8 | H668: 105 | I668: 36.35 | J668: 159.6 | K668: 84 | L668: 13.57 | M668: 139.2 | N668: 137 | O668: 6.26 | P668: 5 | Q668: 10 | R668: 1.35 | S668: 2 | T668: FALSE

Sheet Raw_Data
A1: State | B1: Account length | C1: Area code | D1: International plan | E1: Voice mail plan | F1: Number vmail messages | G1: Total day minutes | H1: Total day calls | I1: Total day charge | J1: Total eve minutes | K1: Total eve calls | L1: Total eve charge | M1: Total night minutes | N1: Total night calls | O1: Total night charge | P1: Total intl minutes | Q1: Total intl calls | R1: Total intl charge | S1: Customer service calls | T1: Churn
A2: LA | B2: 117 | C2: 408 | D2: No | E2: No | F2: 0 | G2: 184.5 | H2: 97 | I2: 31.37 | J2: 351.6 | K2: 80 | L2: 29.89 | M2: 215.8 | N2: 90 | O2: 9.71 | P2: 8.7 | Q2: 4 | R2: 2.35 | S2: 1 | T2: FALSE
A3: IN | B3: 65 | C3: 415 | D3: No | E3: No | F3: 0 | G3: 129.1 | H3: 137 | I3: 21.95 | J3: 228.5 | K3: 83 | L3: 19.42 | M3: 208.8 | N3: 111 | O3: 9.4 | P3: 12.7 | Q3: 6 | R3: 3.43 | S3: 4 | T3: TRUE
A4: NY | B4: 161 | C4: 415 | D4: No | E4: No | F4: 0 | G4: 332.9 | H4: 67 | I4: 56.59 | J4: 317.8 | K4: 97 | L4: 27.01 | M4: 160.6 | N4: 128 | O4: 7.23 | P4: 5.4 | Q4: 9 | R4: 1.46 | S4: 4 | T4: TRUE
A5: SC | B5: 111 | C5: 415 | D5: No | E5: No | F5: 0 | G5: 110.4 | H5: 103 | I5: 18.77 | J5: 137.3 | K5: 102 | L5: 11.67 | M5: 189.6 | N5: 105 | O5: 8.53 | P5: 7.7 | Q5: 6 | R5: 2.08 | S5: 2 | T5: FALSE
A6: HI | B6: 49 | C6: 510 | D6: No | E6: No | F6: 0 | G6: 119.3 | H6: 117 | I6: 20.28 | J6: 215.1 | K6: 109 | L6: 18.28 | M6: 178.7 | N6: 90 | O6: 8.04 | P6: 11.1 | Q6: 1 | R6: 3 | S6: 1 | T6: FALSE
A7: AK | B7: 36 | C7: 408 | D7: No | E7: Yes | F7: 30 | G7: 146.3 | H7: 128 | I7: 24.87 | J7: 162.5 | K7: 80 | L7: 13.81 | M7: 129.3 | N7: 109 | O7: 5.82 | P7: 14.5 | Q7: 6 | R7: 3.92 | S7: 0 | T7: FALSE
A8: MI | B8: 65 | C8: 415 | D8: No | E8: No | F8: 0 | G8: 211.3 | H8: 120 | I8: 35.92 | J8: 162.6 | K8: 122 | L8: 13.82 | M8: 134.7 | N8: 118 | O8: 6.06 | P8: 13.2 | Q8: 5 | R8: 3.56 | S8: 3 | T8: FALSE
A9: ID | B9: 119 | C9: 415 | D9: No | E9: No | F9: 0 | G9: 159.1 | H9: 114 | I9: 27.05 | J9: 231.3 | K9: 117 | L9: 19.66 | M9: 143.2 | N9: 91 | O9: 6.44 | P9: 8.8 | Q9: 3 | R9: 2.38 | S9: 5 | T9: TRUE
A10: VA | B10: 10 | C10: 408 | D10: No | E10: No | F10: 0 | G10: 186.1 | H10: 112 | I10: 31.64 | J10: 190.2 | K10: 66 | L10: 16.17 | M10: 282.8 | N10: 57 | O10: 12.73 | P10: 11.4 | Q10: 6 | R10: 3.08 | S10: 2 | T10: FALSE
A11: WI | B11: 68 | C11: 415 | D11: No | E11: No | F11: 0 | G11: 148.8 | H11: 70 | I11: 25.3 | J11: 246.5 | K11: 164 | L11: 20.95 | M11: 129.8 | N11: 103 | O11: 5.84 | P11: 12.1 | Q11: 3 | R11: 3.27 | S11: 3 | T11: FALSE
A12: MN | B12: 74 | C12: 510 | D12: No | E12: Yes | F12: 33 | G12: 193.7 | H12: 91 | I12: 32.93 | J12: 246.1 | K12: 96 | L12: 20.92 | M12: 138 | N12: 92 | O12: 6.21 | P12: 14.6 | Q12: 3 | R12: 3.94 | S12: 2 | T12: FALSE
A13: HI | B13: 85 | C13: 415 | D13: No | E13: No | F13: 0 | G13: 235.8 | H13: 109 | I13: 40.09 | J13: 157.2 | K13: 94 | L13: 13.36 | M13: 188.2 | N13: 99 | O13: 8.47 | P13: 12 | Q13: 3 | R13: 3.24 | S13: 0 | T13: FALSE
... A668: CT | B668: 184 | C668: 510 | D668: Yes | E668: No | F668: 0 | G668: 213.8 | H668: 105 | I668: 36.35 | J668: 159.6 | K668: 84 | L668: 13.57 | M668: 139.2 | N668: 137 | O668: 6.26 | P668: 5 | Q668: 10 | R668: 1.35 | S668: 2 | T668: FALSE
A669: Total | B669: =SUBTOTAL(104,Table13[Account length]) -> 232 | F669: =SUBTOTAL(104,Table13[Number vmail messages]) -> 51 | G669: =SUBTOTAL(104,Table13[Total day minutes]) -> 334.3 | H669: =SUBTOTAL(104,Table13[Total day calls]) -> 165 | I669: =SUBTOTAL(101,Table13[Total day charge]) -> 30.761769 | J669: =SUBTOTAL(101,Table13[Total eve minutes]) -> 203.35532 | K669: =SUBTOTAL(101,Table13[Total eve calls]) -> 100.47676 | L669: =SUBTOTAL(101,Table13[Total eve charge]) -> 17.285262 | M669: =SUBTOTAL(101,Table13[Total night minutes]) -> 199.68531 | N669: =SUBTOTAL(101,Table13[Total night calls]) -> 100.11394 | O669: =SUBTOTAL(101,Table13[Total night charge]) -> 8.985907 | P669: =SUBTOTAL(101,Table13[Total intl minutes]) -> 10.238381 | Q669: =SUBTOTAL(101,Table13[Total intl calls]) -> 4.5277361 | R669: =SUBTOTAL(101,Table13[Total intl charge]) -> 2.7649475 | T669: =SUBTOTAL(103,Table13[Churn]) -> 667

Sheet Logical
A1: Customer State | B1: Churn | C1: Churn Status | D1: Customer Type | E1: High Day Usage | F1: Risk Level | G1: Plan Status | H1: Service Issue | I1: SWITCH Result | J1: ISERROR | K1: ISBLANK | L1: ISNUMBER
A2: =Raw_Data!A2 -> LA | B2: =Raw_Data!T2 -> FALSE | C2: =IF(B2=TRUE,"Churned","Retained") -> Retained | D2: =IF(Raw_Data!S2=0,"Low Contact",IF(Raw_Data!S2<=2,"Normal Contact","High Contact")) -> Normal Contact | E2: =IF(AND(Raw_Data!G2>200,Raw_Data!H2>100),"High Usage","Normal Usage") -> Normal Usage | F2: {=_xlfn.IFS(B2=TRUE,"High Risk",AND(Raw_Data!S2>=3,Raw_Data!G2>200),"High Risk",Raw_Data!S2>=2,"Medium Risk",TRUE,"Low Risk")} -> Low Risk | G2: =IF(OR(Raw_Data!D2="Yes",Raw_Data!E2="Yes"),"Has Plan","No Special Plan") -> No Special Plan | H2: =IF(NOT(Raw_Data!S2>=3),"Normal Service Contact","Frequent Service Contact") -> Normal Service Contact | I2: {=_xlfn.SWITCH(Raw_Data!D2,"Yes","International Customer","No","Domestic Plan","Unknown")} -> Domestic Plan | J2: =IF(ISERROR(Raw_Data!G2/0),"Error","Valid") -> Error | K2: =IF(ISBLANK(Raw_Data!A2),"Missing","Available") -> Available | L2: =IF(ISNUMBER(Raw_Data!G2),"Numeric","Not Numeric") -> Numeric
A3: =Raw_Data!A3 -> IN | B3: =Raw_Data!T3 -> TRUE | C3: =IF(B3=TRUE,"Churned","Retained") -> Churned | D3: =IF(Raw_Data!S3=0,"Low Contact",IF(Raw_Data!S3<=2,"Normal Contact","High Contact")) -> High Contact | E3: =IF(AND(Raw_Data!G3>200,Raw_Data!H3>100),"High Usage","Normal Usage") -> Normal Usage | F3: {=_xlfn.IFS(B3=TRUE,"High Risk",AND(Raw_Data!S3>=3,Raw_Data!G3>200),"High Risk",Raw_Data!S3>=2,"Medium Risk",TRUE,"Low Risk")} -> High Risk | G3: =IF(OR(Raw_Data!D3="Yes",Raw_Data!E3="Yes"),"Has Plan","No Special Plan") -> No Special Plan | H3: =IF(NOT(Raw_Data!S3>=3),"Normal Service Contact","Frequent Service Contact") -> Frequent Service Contact | I3: {=_xlfn.SWITCH(Raw_Data!D3,"Yes","International Customer","No","Domestic Plan","Unknown")} -> Domestic Plan | J3: =IF(ISERROR(Raw_Data!G3/0),"Error","Valid") -> Error | K3: =IF(ISBLANK(Raw_Data!A3),"Missing","Available") -> Available | L3: =IF(ISNUMBER(Raw_Data!G3),"Numeric","Not Numeric") -> Numeric
A4: =Raw_Data!A4 -> NY | B4: =Raw_Data!T4 -> TRUE | C4: =IF(B4=TRUE,"Churned","Retained") -> Churned | D4: =IF(Raw_Data!S4=0,"Low Contact",IF(Raw_Data!S4<=2,"Normal Contact","High Contact")) -> High Contact | E4: =IF(AND(Raw_Data!G4>200,Raw_Data!H4>100),"High Usage","Normal Usage") -> Normal Usage | F4: {=_xlfn.IFS(B4=TRUE,"High Risk",AND(Raw_Data!S4>=3,Raw_Data!G4>200),"High Risk",Raw_Data!S4>=2,"Medium Risk",TRUE,"Low Risk")} -> High Risk | G4: =IF(OR(Raw_Data!D4="Yes",Raw_Data!E4="Yes"),"Has Plan","No Special Plan") -> No Special Plan | H4: =IF(NOT(Raw_Data!S4>=3),"Normal Service Contact","Frequent Service Contact") -> Frequent Service Contact | I4: {=_xlfn.SWITCH(Raw_Data!D4,"Yes","International Customer","No","Domestic Plan","Unknown")} -> Domestic Plan | J4: =IF(ISERROR(Raw_Data!G4/0),"Error","Valid") -> Error | K4: =IF(ISBLANK(Raw_Data!A4),"Missing","Available") -> Available | L4: =IF(ISNUMBER(Raw_Data!G4),"Numeric","Not Numeric") -> Numeric
A5: =Raw_Data!A5 -> SC | B5: =Raw_Data!T5 -> FALSE | C5: =IF(B5=TRUE,"Churned","Retained") -> Retained | D5: =IF(Raw_Data!S5=0,"Low Contact",IF(Raw_Data!S5<=2,"Normal Contact","High Contact")) -> Normal Contact | E5: =IF(AND(Raw_Data!G5>200,Raw_Data!H5>100),"High Usage","Normal Usage") -> Normal Usage | F5: {=_xlfn.IFS(B5=TRUE,"High Risk",AND(Raw_Data!S5>=3,Raw_Data!G5>200),"High Risk",Raw_Data!S5>=2,"Medium Risk",TRUE,"Low Risk")} -> Medium Risk | G5: =IF(OR(Raw_Data!D5="Yes",Raw_Data!E5="Yes"),"Has Plan","No Special Plan") -> No Special Plan | H5: =IF(NOT(Raw_Data!S5>=3),"Normal Service Contact","Frequent Service Contact") -> Normal Service Contact | I5: {=_xlfn.SWITCH(Raw_Data!D5,"Yes","International Customer","No","Domestic Plan","Unknown")} -> Domestic Plan | J5: =IF(ISERROR(Raw_Data!G5/0),"Error","Valid") -> Error | K5: =IF(ISBLANK(Raw_Data!A5),"Missing","Available") -> Available | L5: =IF(ISNUMBER(Raw_Data!G5),"Numeric","Not Numeric") -> Numeric
A6: =Raw_Data!A6 -> HI | B6: =Raw_Data!T6 -> FALSE | C6: =IF(B6=TRUE,"Churned","Retained") -> Retained | D6: =IF(Raw_Data!S6=0,"Low Contact",IF(Raw_Data!S6<=2,"Normal Contact","High Contact")) -> Normal Contact | E6: =IF(AND(Raw_Data!G6>200,Raw_Data!H6>100),"High Usage","Normal Usage") -> Normal Usage | F6: {=_xlfn.IFS(B6=TRUE,"High Risk",AND(Raw_Data!S6>=3,Raw_Data!G6>200),"High Risk",Raw_Data!S6>=2,"Medium Risk",TRUE,"Low Risk")} -> Low Risk | G6: =IF(OR(Raw_Data!D6="Yes",Raw_Data!E6="Yes"),"Has Plan","No Special Plan") -> No Special Plan | H6: =IF(NOT(Raw_Data!S6>=3),"Normal Service Contact","Frequent Service Contact") -> Normal Service Contact | I6: {=_xlfn.SWITCH(Raw_Data!D6,"Yes","International Customer","No","Domestic Plan","Unknown")} -> Domestic Plan | J6: =IF(ISERROR(Raw_Data!G6/0),"Error","Valid") -> Error | K6: =IF(ISBLANK(Raw_Data!A6),"Missing","Available") -> Available | L6: =IF(ISNUMBER(Raw_Data!G6),"Numeric","Not Numeric") -> Numeric
A7: =Raw_Data!A7 -> AK | B7: =Raw_Data!T7 -> FALSE | C7: =IF(B7=TRUE,"Churned","Retained") -> Retained | D7: =IF(Raw_Data!S7=0,"Low Contact",IF(Raw_Data!S7<=2,"Normal Contact","High Contact")) -> Low Contact | E7: =IF(AND(Raw_Data!G7>200,Raw_Data!H7>100),"High Usage","Normal Usage") -> Normal Usage | F7: {=_xlfn.IFS(B7=TRUE,"High Risk",AND(Raw_Data!S7>=3,Raw_Data!G7>200),"High Risk",Raw_Data!S7>=2,"Medium Risk",TRUE,"Low Risk")} -> Low Risk | G7: =IF(OR(Raw_Data!D7="Yes",Raw_Data!E7="Yes"),"Has Plan","No Special Plan") -> Has Plan | H7: =IF(NOT(Raw_Data!S7>=3),"Normal Service Contact","Frequent Service Contact") -> Normal Service Contact | I7: {=_xlfn.SWITCH(Raw_Data!D7,"Yes","International Customer","No","Domestic Plan","Unknown")} -> Domestic Plan | J7: =IF(ISERROR(Raw_Data!G7/0),"Error","Valid") -> Error | K7: =IF(ISBLANK(Raw_Data!A7),"Missing","Available") -> Available | L7: =IF(ISNUMBER(Raw_Data!G7),"Numeric","Not Numeric") -> Numeric
A8: =Raw_Data!A8 -> MI | B8: =Raw_Data!T8 -> FALSE | C8: =IF(B8=TRUE,"Churned","Retained") -> Retained | D8: =IF(Raw_Data!S8=0,"Low Contact",IF(Raw_Data!S8<=2,"Normal Contact","High Contact")) -> High Contact | E8: =IF(AND(Raw_Data!G8>200,Raw_Data!H8>100),"High Usage","Normal Usage") -> High Usage | F8: {=_xlfn.IFS(B8=TRUE,"High Risk",AND(Raw_Data!S8>=3,Raw_Data!G8>200),"High Risk",Raw_Data!S8>=2,"Medium Risk",TRUE,"Low Risk")} -> High Risk | G8: =IF(OR(Raw_Data!D8="Yes",Raw_Data!E8="Yes"),"Has Plan","No Special Plan") -> No Special Plan | H8: =IF(NOT(Raw_Data!S8>=3),"Normal Service Contact","Frequent Service Contact") -> Frequent Service Contact | I8: {=_xlfn.SWITCH(Raw_Data!D8,"Yes","International Customer","No","Domestic Plan","Unknown")} -> Domestic Plan | J8: =IF(ISERROR(Raw_Data!G8/0),"Error","Valid") -> Error | K8: =IF(ISBLANK(Raw_Data!A8),"Missing","Available") -> Available | L8: =IF(ISNUMBER(Raw_Data!G8),"Numeric","Not Numeric") -> Numeric
A9: =Raw_Data!A9 -> ID | B9: =Raw_Data!T9 -> TRUE | C9: =IF(B9=TRUE,"Churned","Retained") -> Churned | D9: =IF(Raw_Data!S9=0,"Low Contact",IF(Raw_Data!S9<=2,"Normal Contact","High Contact")) -> High Contact | E9: =IF(AND(Raw_Data!G9>200,Raw_Data!H9>100),"High Usage","Normal Usage") -> Normal Usage | F9: {=_xlfn.IFS(B9=TRUE,"High Risk",AND(Raw_Data!S9>=3,Raw_Data!G9>200),"High Risk",Raw_Data!S9>=2,"Medium Risk",TRUE,"Low Risk")} -> High Risk | G9: =IF(OR(Raw_Data!D9="Yes",Raw_Data!E9="Yes"),"Has Plan","No Special Plan") -> No Special Plan | H9: =IF(NOT(Raw_Data!S9>=3),"Normal Service Contact","Frequent Service Contact") -> Frequent Service Contact | I9: {=_xlfn.SWITCH(Raw_Data!D9,"Yes","International Customer","No","Domestic Plan","Unknown")} -> Domestic Plan | J9: =IF(ISERROR(Raw_Data!G9/0),"Error","Valid") -> Error | K9: =IF(ISBLANK(Raw_Data!A9),"Missing","Available") -> Available | L9: =IF(ISNUMBER(Raw_Data!G9),"Numeric","Not Numeric") -> Numeric
A10: =Raw_Data!A10 -> VA | B10: =Raw_Data!T10 -> FALSE | C10: =IF(B10=TRUE,"Churned","Retained") -> Retained | D10: =IF(Raw_Data!S10=0,"Low Contact",IF(Raw_Data!S10<=2,"Normal Contact","High Contact")) -> Normal Contact | E10: =IF(AND(Raw_Data!G10>200,Raw_Data!H10>100),"High Usage","Normal Usage") -> Normal Usage | F10: {=_xlfn.IFS(B10=TRUE,"High Risk",AND(Raw_Data!S10>=3,Raw_Data!G10>200),"High Risk",Raw_Data!S10>=2,"Medium Risk",TRUE,"Low Risk")} -> Medium Risk | G10: =IF(OR(Raw_Data!D10="Yes",Raw_Data!E10="Yes"),"Has Plan","No Special Plan") -> No Special Plan | H10: =IF(NOT(Raw_Data!S10>=3),"Normal Service Contact","Frequent Service Contact") -> Normal Service Contact | I10: {=_xlfn.SWITCH(Raw_Data!D10,"Yes","International Customer","No","Domestic Plan","Unknown")} -> Domestic Plan | J10: =IF(ISERROR(Raw_Data!G10/0),"Error","Valid") -> Error | K10: =IF(ISBLANK(Raw_Data!A10),"Missing","Available") -> Available | L10: =IF(ISNUMBER(Raw_Data!G10),"Numeric","Not Numeric") -> Numeric
A11: =Raw_Data!A11 -> WI | B11: =Raw_Data!T11 -> FALSE | C11: =IF(B11=TRUE,"Churned","Retained") -> Retained | D11: =IF(Raw_Data!S11=0,"Low Contact",IF(Raw_Data!S11<=2,"Normal Contact","High Contact")) -> High Contact | E11: =IF(AND(Raw_Data!G11>200,Raw_Data!H11>100),"High Usage","Normal Usage") -> Normal Usage | F11: {=_xlfn.IFS(B11=TRUE,"High Risk",AND(Raw_Data!S11>=3,Raw_Data!G11>200),"High Risk",Raw_Data!S11>=2,"Medium Risk",TRUE,"Low Risk")} -> Medium Risk | G11: =IF(OR(Raw_Data!D11="Yes",Raw_Data!E11="Yes"),"Has Plan","No Special Plan") -> No Special Plan | H11: =IF(NOT(Raw_Data!S11>=3),"Normal Service Contact","Frequent Service Contact") -> Frequent Service Contact | I11: {=_xlfn.SWITCH(Raw_Data!D11,"Yes","International Customer","No","Domestic Plan","Unknown")} -> Domestic Plan | J11: =IF(ISERROR(Raw_Data!G11/0),"Error","Valid") -> Error | K11: =IF(ISBLANK(Raw_Data!A11),"Missing","Available") -> Available | L11: =IF(ISNUMBER(Raw_Data!G11),"Numeric","Not Numeric") -> Numeric
A12: =Raw_Data!A12 -> MN | B12: =Raw_Data!T12 -> FALSE | C12: =IF(B12=TRUE,"Churned","Retained") -> Retained | D12: =IF(Raw_Data!S12=0,"Low Contact",IF(Raw_Data!S12<=2,"Normal Contact","High Contact")) -> Normal Contact | E12: =IF(AND(Raw_Data!G12>200,Raw_Data!H12>100),"High Usage","Normal Usage") -> Normal Usage | F12: {=_xlfn.IFS(B12=TRUE,"High Risk",AND(Raw_Data!S12>=3,Raw_Data!G12>200),"High Risk",Raw_Data!S12>=2,"Medium Risk",TRUE,"Low Risk")} -> Medium Risk | G12: =IF(OR(Raw_Data!D12="Yes",Raw_Data!E12="Yes"),"Has Plan","No Special Plan") -> Has Plan | H12: =IF(NOT(Raw_Data!S12>=3),"Normal Service Contact","Frequent Service Contact") -> Normal Service Contact | I12: {=_xlfn.SWITCH(Raw_Data!D12,"Yes","International Customer","No","Domestic Plan","Unknown")} -> Domestic Plan | J12: =IF(ISERROR(Raw_Data!G12/0),"Error","Valid") -> Error | K12: =IF(ISBLANK(Raw_Data!A12),"Missing","Available") -> Available | L12: =IF(ISNUMBER(Raw_Data!G12),"Numeric","Not Numeric") -> Numeric
A13: =Raw_Data!A13 -> HI | B13: =Raw_Data!T13 -> FALSE | C13: =IF(B13=TRUE,"Churned","Retained") -> Retained | D13: =IF(Raw_Data!S13=0,"Low Contact",IF(Raw_Data!S13<=2,"Normal Contact","High Contact")) -> Low Contact | E13: =IF(AND(Raw_Data!G13>200,Raw_Data!H13>100),"High Usage","Normal Usage") -> High Usage | F13: {=_xlfn.IFS(B13=TRUE,"High Risk",AND(Raw_Data!S13>=3,Raw_Data!G13>200),"High Risk",Raw_Data!S13>=2,"Medium Risk",TRUE,"Low Risk")} -> Low Risk | G13: =IF(OR(Raw_Data!D13="Yes",Raw_Data!E13="Yes"),"Has Plan","No Special Plan") -> No Special Plan | H13: =IF(NOT(Raw_Data!S13>=3),"Normal Service Contact","Frequent Service Contact") -> Normal Service Contact | I13: {=_xlfn.SWITCH(Raw_Data!D13,"Yes","International Customer","No","Domestic Plan","Unknown")} -> Domestic Plan | J13: =IF(ISERROR(Raw_Data!G13/0),"Error","Valid") -> Error | K13: =IF(ISBLANK(Raw_Data!A13),"Missing","Available") -> Available | L13: =IF(ISNUMBER(Raw_Data!G13),"Numeric","Not Numeric") -> Numeric
... A668: =Raw_Data!A668 -> CT | B668: =Raw_Data!T668 -> FALSE | C668: =IF(B668=TRUE,"Churned","Retained") -> Retained | D668: =IF(Raw_Data!S668=0,"Low Contact",IF(Raw_Data!S668<=2,"Normal Contact","High Contact")) -> Normal Contact | E668: =IF(AND(Raw_Data!G668>200,Raw_Data!H668>100),"High Usage","Normal Usage") -> High Usage | F668: {=_xlfn.IFS(B668=TRUE,"High Risk",AND(Raw_Data!S668>=3,Raw_Data!G668>200),"High Risk",Raw_Data!S668>=2,"Medium Risk",TRUE,"Low Risk")} -> Medium Risk | G668: =IF(OR(Raw_Data!D668="Yes",Raw_Data!E668="Yes"),"Has Plan","No Special Plan") -> Has Plan | H668: =IF(NOT(Raw_Data!S668>=3),"Normal Service Contact","Frequent Service Contact") -> Normal Service Contact | I668: {=_xlfn.SWITCH(Raw_Data!D668,"Yes","International Customer","No","Domestic Plan","Unknown")} -> International Customer | J668: =IF(ISERROR(Raw_Data!G668/0),"Error","Valid") -> Error | K668: =IF(ISBLANK(Raw_Data!A668),"Missing","Available") -> Available | L668: =IF(ISNUMBER(Raw_Data!G668),"Numeric","Not Numeric") -> Numeric
A669: Total | L669: =SUBTOTAL(103,Table3[ISNUMBER]) -> 667

Sheet Lookups
A1: Area Code | B1: Region | D1: Area Code | E1: VLOOKUP Region | G1: Area Code | H1: XLOOKUP Region | J1: Area Code | K1: INDEX-MATCH Region | M1: 408 | N1: 415 | O1: 510 | Q1: Area Code | R1: Hlookup
A2: 408 | B2: Area 408 | D2: 408 | E2: =VLOOKUP(D2,$A$2:$B$4,2,FALSE) -> Area 408 | G2: 415 | H2: =_xlfn.XLOOKUP(G2,$A$2:$A$4,$B$2:$B$4,"Not Found") -> Area 415 | J2: 510 | K2: =INDEX($B$2:$B$4,MATCH(J2,$A$2:$A$4,0)) -> Area 510 | M2: Area 408 | N2: Area 415 | O2: Area 510 | Q2: 415 | R2: =HLOOKUP(Q2,$M$1:$O$2,2,FALSE) -> Area 415
A3: 415 | B3: Area 415
A4: 510 | B4: Area 510
D5: Customer Row | E5: Churn Status
D6: 10 | E6: {=_xlfn.XLOOKUP(D6,ROW(Raw_Data!T2:T668),Raw_Data!T2:T668)} -> FALSE
D9: Churn Status | E9: =INDEX(Raw_Data!T2:T668,MATCH(MAX(Raw_Data!G2:G668),Raw_Data!G2:G668,0)) -> TRUE
D10: Highest Day Minutes | E10: {=INDIRECT("Raw_Data!G"&ROW())} -> 186.1
D11: Offset | E11: =OFFSET(Raw_Data!G2,0,2) -> 31.37

Sheet Arrays
A1: DYNAMIC ARRAY ANALYSIS
A3: Unique Status | C3: Churned Customers | E3: High Day Usage | G3: Sorted Day Minutes | I3: Customer IDs
A4: {=_xlfn.UNIQUE(Raw_Data!A2:A668)} -> LA | C4: {=_xlfn.UNIQUE(Raw_Data!D2:D668)} -> No
A5: IN | C5: Yes
A6: NY
A7: SC
A8: HI
A9: AK
A10: MI
A11: ID
A12: VA
A13: WI
A14: MN
A15: VT
A16: MT
A17: MA
... A54: GA

Sheet Cleaning
A1: Original State | B1: TRIM | C1: CLEAN | D1: TRIM + CLEAN | E1: Substitute | F1: Blank Check | G1: Duplicate Check
A2: {=(Raw_Data!A2:A668)} -> LA | B2: =TRIM(A2) -> LA | C2: =CLEAN(A2) -> LA | D2: =TRIM(CLEAN(A2)) -> LA | E2: =SUBSTITUTE(D2," ","") -> LA | F2: =IF(ISBLANK(A2),"Missing","Complete") -> Complete | G2: =IF(COUNTIF($A$2:A2,A2)>1,"Duplicate","Unique") -> Unique
A3: IN | B3: =TRIM(A3) -> IN | C3: =CLEAN(A3) -> IN | D3: =TRIM(CLEAN(A3)) -> IN | E3: =SUBSTITUTE(D3," ","") -> IN | F3: =IF(ISBLANK(A3),"Missing","Complete") -> Complete | G3: =IF(COUNTIF($A$2:A3,A3)>1,"Duplicate","Unique") -> Unique
A4: NY | B4: =TRIM(A4) -> NY | C4: =CLEAN(A4) -> NY | D4: =TRIM(CLEAN(A4)) -> NY | E4: =SUBSTITUTE(D4," ","") -> NY | F4: =IF(ISBLANK(A4),"Missing","Complete") -> Complete | G4: =IF(COUNTIF($A$2:A4,A4)>1,"Duplicate","Unique") -> Unique
A5: SC | B5: =TRIM(A5) -> SC | C5: =CLEAN(A5) -> SC | D5: =TRIM(CLEAN(A5)) -> SC | E5: =SUBSTITUTE(D5," ","") -> SC | F5: =IF(ISBLANK(A5),"Missing","Complete") -> Complete | G5: =IF(COUNTIF($A$2:A5,A5)>1,"Duplicate","Unique") -> Unique
A6: HI | B6: =TRIM(A6) -> HI | C6: =CLEAN(A6) -> HI | D6: =TRIM(CLEAN(A6)) -> HI | E6: =SUBSTITUTE(D6," ","") -> HI | F6: =IF(ISBLANK(A6),"Missing","Complete") -> Complete | G6: =IF(COUNTIF($A$2:A6,A6)>1,"Duplicate","Unique") -> Unique
A7: AK | B7: =TRIM(A7) -> AK | C7: =CLEAN(A7) -> AK | D7: =TRIM(CLEAN(A7)) -> AK | E7: =SUBSTITUTE(D7," ","") -> AK | F7: =IF(ISBLANK(A7),"Missing","Complete") -> Complete | G7: =IF(COUNTIF($A$2:A7,A7)>1,"Duplicate","Unique") -> Unique
A8: MI | B8: =TRIM(A8) -> MI | C8: =CLEAN(A8) -> MI | D8: =TRIM(CLEAN(A8)) -> MI | E8: =SUBSTITUTE(D8," ","") -> MI | F8: =IF(ISBLANK(A8),"Missing","Complete") -> Complete | G8: =IF(COUNTIF($A$2:A8,A8)>1,"Duplicate","Unique") -> Unique
A9: ID | B9: =TRIM(A9) -> ID | C9: =CLEAN(A9) -> ID | D9: =TRIM(CLEAN(A9)) -> ID | E9: =SUBSTITUTE(D9," ","") -> ID | F9: =IF(ISBLANK(A9),"Missing","Complete") -> Complete | G9: =IF(COUNTIF($A$2:A9,A9)>1,"Duplicate","Unique") -> Unique
A10: VA | B10: =TRIM(A10) -> VA | C10: =CLEAN(A10) -> VA | D10: =TRIM(CLEAN(A10)) -> VA | E10: =SUBSTITUTE(D10," ","") -> VA | F10: =IF(ISBLANK(A10),"Missing","Complete") -> Complete | G10: =IF(COUNTIF($A$2:A10,A10)>1,"Duplicate","Unique") -> Unique
A11: WI | B11: =TRIM(A11) -> WI | C11: =CLEAN(A11) -> WI | D11: =TRIM(CLEAN(A11)) -> WI | E11: =SUBSTITUTE(D11," ","") -> WI | F11: =IF(ISBLANK(A11),"Missing","Complete") -> Complete | G11: =IF(COUNTIF($A$2:A11,A11)>1,"Duplicate","Unique") -> Unique
A12: MN | B12: =TRIM(A12) -> MN | C12: =CLEAN(A12) -> MN | D12: =TRIM(CLEAN(A12)) -> MN | E12: =SUBSTITUTE(D12," ","") -> MN | F12: =IF(ISBLANK(A12),"Missing","Complete") -> Complete | G12: =IF(COUNTIF($A$2:A12,A12)>1,"Duplicate","Unique") -> Unique
A13: HI | B13: =TRIM(A13) -> HI | C13: =CLEAN(A13) -> HI | D13: =TRIM(CLEAN(A13)) -> HI | E13: =SUBSTITUTE(D13," ","") -> HI | F13: =IF(ISBLANK(A13),"Missing","Complete") -> Complete | G13: =IF(COUNTIF($A$2:A13,A13)>1,"Duplicate","Unique") -> Duplicate
A14: MN | B14: =TRIM(A14) -> MN | C14: =CLEAN(A14) -> MN | D14: =TRIM(CLEAN(A14)) -> MN | E14: =SUBSTITUTE(D14," ","") -> MN | F14: =IF(ISBLANK(A14),"Missing","Complete") -> Complete | G14: =IF(COUNTIF($A$2:A14,A14)>1,"Duplicate","Unique") -> Duplicate
... A668: CT | B668: =TRIM(A668) -> CT | C668: =CLEAN(A668) -> CT | D668: =TRIM(CLEAN(A668)) -> CT | E668: =SUBSTITUTE(D668," ","") -> CT | F668: =IF(ISBLANK(A668),"Missing","Complete") -> Complete | G668: =IF(COUNTIF($A$2:A668,A668)>1,"Duplicate","Unique") -> Duplicate

Sheet Statistics
A1: DESCRIPTIVE STATISTICS
A3: Metric | B3: Account Lenth | C3: Day Minutes | D3: Day Calls | E3: Day Charge | F3: Eve Minutes | G3: Night Minutes | H3: Intl minutes | I3: Servie Calls
A4: Average | B4: =AVERAGE(Raw_Data!F2:F668) -> 8.4077961 | C4: =AVERAGE(Raw_Data!G2:G668) -> 180.94813 | D4: =AVERAGE(Raw_Data!H2:H668) -> 100.93703 | E4: =AVERAGE(Raw_Data!I2:I668) -> 30.761769 | F4: =AVERAGE(Raw_Data!J2:J668) -> 203.35532 | G4: =AVERAGE(Raw_Data!K2:K668) -> 100.47676 | H4: =AVERAGE(Raw_Data!L2:L668) -> 17.285262 | I4: =AVERAGE(Raw_Data!M2:M668) -> 199.68531
A5: median | B5: =MEDIAN(Raw_Data!B2:B668) -> 102 | C5: =MEDIAN(Raw_Data!C2:C668) -> 415 | D5: =MEDIAN(Raw_Data!H2:H668) -> 101 | E5: =MEDIAN(Raw_Data!I2:I668) -> 30.31 | F5: =MEDIAN(Raw_Data!J2:J668) -> 203.7 | G5: =MEDIAN(Raw_Data!K2:K668) -> 101 | H5: =MEDIAN(Raw_Data!L2:L668) -> 17.31 | I5: =MEDIAN(Raw_Data!M2:M668) -> 201.6
A6: Mode | B6: =_xlfn.MODE.SNGL(Raw_Data!B2:B668) -> 95 | C6: =_xlfn.MODE.SNGL(Raw_Data!G2:G668) -> 189.8 | D6: =_xlfn.MODE.SNGL(Raw_Data!H2:H668) -> 102 | E6: =_xlfn.MODE.SNGL(Raw_Data!I2:I668) -> 32.27 | F6: =_xlfn.MODE.SNGL(Raw_Data!J2:J668) -> 183.6 | G6: =_xlfn.MODE.SNGL(Raw_Data!K2:K668) -> 101 | H6: =_xlfn.MODE.SNGL(Raw_Data!L2:L668) -> 18.33 | I6: =_xlfn.MODE.SNGL(Raw_Data!M2:M668) -> 188.2
A7: Variance | B7: =_xlfn.VAR.S(Raw_Data!F2:F668) -> 195.84546 | C7: =_xlfn.VAR.S(Raw_Data!G2:G668) -> 3081.2078 | D7: =_xlfn.VAR.S(Raw_Data!H2:H668) -> 416.02906 | E7: =_xlfn.VAR.S(Raw_Data!I2:I668) -> 89.046843 | F7: =_xlfn.VAR.S(Raw_Data!J2:J668) -> 2472.0057 | G7: =_xlfn.VAR.S(Raw_Data!K2:K668) -> 359.03662 | H7: =_xlfn.VAR.S(Raw_Data!L2:L668) -> 17.860429 | I7: =_xlfn.VAR.S(Raw_Data!M2:M668) -> 2476.0507
A8: Standard Deviation | B8: =_xlfn.STDEV.S(Raw_Data!G2:G668) -> 55.508628 | C8: =_xlfn.STDEV.S(Raw_Data!H2:H668) -> 20.39679 | D8: =_xlfn.STDEV.S(Raw_Data!I2:I668) -> 9.4364635 | E8: =_xlfn.STDEV.S(Raw_Data!J2:J668) -> 49.719268 | F8: =_xlfn.STDEV.S(Raw_Data!K2:K668) -> 18.948262 | G8: =_xlfn.STDEV.S(Raw_Data!L2:L668) -> 4.2261601 | H8: =_xlfn.STDEV.S(Raw_Data!M2:M668) -> 49.759931 | I8: =_xlfn.STDEV.S(Raw_Data!N2:N668) -> 20.172505
A9: Minimum | B9: =MIN(Raw_Data!B2:B668) -> 1 | C9: =MIN(Raw_Data!G2:G668) -> 25.9 | D9: =MIN(Raw_Data!H2:H668) -> 30 | E9: =MIN(Raw_Data!I2:I668) -> 4.4 | F9: =MIN(Raw_Data!J2:J668) -> 48.1 | G9: =MIN(Raw_Data!K2:K668) -> 37 | H9: =MIN(Raw_Data!L2:L668) -> 4.09 | I9: =MIN(Raw_Data!M2:M668) -> 23.2
A10: Maximum | B10: =MAX(Raw_Data!F2:F668) -> 51 | C10: =MAX(Raw_Data!G2:G668) -> 334.3 | D10: =MAX(Raw_Data!H2:H668) -> 165 | E10: =MAX(Raw_Data!I2:I668) -> 56.83 | F10: =MAX(Raw_Data!J2:J668) -> 361.8 | G10: =MAX(Raw_Data!K2:K668) -> 168 | H10: =MAX(Raw_Data!L2:L668) -> 30.75 | I10: =MAX(Raw_Data!M2:M668) -> 367.7
A13: CHUN ANALYSIS
A15: Total customers | B15: =COUNTA(Raw_Data!A2:A668) -> 667
A16: Churnrd customers | B16: =COUNTIF(Raw_Data!T2:T668,TRUE) -> 95
A17: Retained customers | B17: =COUNTIF(Raw_Data!T2:T668,FALSE) -> 572
A18: Churn rate | B18: =B16/B15 -> 0.14242879
A21: CHURN BY INTERNATIONAL PLAN
A23: Plan | B23: Total Customers | C23: Churned | D23: Churn Rate
A24: Yes | B24: =COUNTIF(Raw_Data!D2:D668,A24) -> 53 | C24: =COUNTIFS(Raw_Data!D2:D668,A24,Raw_Data!T2:T668,TRUE) -> 19 | D24: =C24/B24 -> 0.35849057
A25: No | B25: =COUNTIF(Raw_Data!D3:D669,A25) -> 613 | C25: =COUNTIFS(Raw_Data!D3:D669,A25,Raw_Data!T3:T669,TRUE) -> 76 | D25: =C25/B25 -> 0.12398042
A28: SERVICE CALL ANALYSIS
A30: Service calls | B30: Customers | C30: Churned | D30: Churn rate
A31: 0 | B31: =COUNTIF(Raw_Data!S2:S6668,A31) -> 142 | C31: =COUNTIFS(Raw_Data!S2:S668,A31,Raw_Data!T2:T668,TRUE) -> 13 | D31: =IFERROR(C31/B31,0) -> 0.091549296
A32: 1 | B32: =COUNTIF(Raw_Data!S3:S6669,A32) -> 235 | C32: =COUNTIFS(Raw_Data!S3:S669,A32,Raw_Data!T3:T669,TRUE) -> 23 | D32: =IFERROR(C32/B32,0) -> 0.09787234
A33: 2 | B33: =COUNTIF(Raw_Data!S4:S6670,A33) -> 151 | C33: =COUNTIFS(Raw_Data!S4:S670,A33,Raw_Data!T4:T670,TRUE) -> 25 | D33: =IFERROR(C33/B33,0) -> 0.16556291
A34: 3 | B34: =COUNTIF(Raw_Data!S5:S6671,A34) -> 81 | C34: =COUNTIFS(Raw_Data!S5:S671,A34,Raw_Data!T5:T671,TRUE) -> 7 | D34: =IFERROR(C34/B34,0) -> 0.086419753
A35: 4 | B35: =COUNTIF(Raw_Data!S6:S6672,A35) -> 31 | C35: =COUNTIFS(Raw_Data!S6:S672,A35,Raw_Data!T6:T672,TRUE) -> 10 | D35: =IFERROR(C35/B35,0) -> 0.32258065
A36: 5 | B36: =COUNTIF(Raw_Data!S7:S6673,A36) -> 17 | C36: =COUNTIFS(Raw_Data!S7:S673,A36,Raw_Data!T7:T673,TRUE) -> 11 | D36: =IFERROR(C36/B36,0) -> 0.64705882
A37: 6 | B37: =COUNTIF(Raw_Data!S8:S6674,A37) -> 5 | C37: =COUNTIFS(Raw_Data!S8:S674,A37,Raw_Data!T8:T674,TRUE) -> 4 | D37: =IFERROR(C37/B37,0) -> 0.8
A38: 7 | B38: =COUNTIF(Raw_Data!S9:S6675,A38) -> 1 | C38: =COUNTIFS(Raw_Data!S9:S675,A38,Raw_Data!T9:T675,TRUE) -> 0 | D38: =IFERROR(C38/B38,0) -> 0
A39: 8 | B39: =COUNTIF(Raw_Data!S10:S6676,A39) -> 1 | C39: =COUNTIFS(Raw_Data!S10:S676,A39,Raw_Data!T10:T676,TRUE) -> 0 | D39: =IFERROR(C39/B39,0) -> 0
A42: CORRELATION ANALYSIS | D42: REGRESSION ANALYSIS
A44: Variables | B44: correlation | D44: Slope | E44: =SLOPE(Raw_Data!I2:I668,Raw_Data!G2:G668) -> 0.16999993
A45: Day Minutes Vs Day Charge | B45: =CORREL(Raw_Data!G2:G668,Raw_Data!I2:I668) -> 0.99999995 | D45: Intercept | E45: =INTERCEPT(Raw_Data!I2:I668,Raw_Data!G2:G668) -> 0.00059977462
A46: Eve Minutes Vs Eve Charge | B46: =CORREL(Raw_Data!J2:J668,Raw_Data!L2:L668) -> 0.99999975 | D46: R-Squared | E46: =RSQ(Raw_Data!I2:I668,Raw_Data!G2:G668) -> 0.99999991
A47: Night Minutes Vs Night Charge | B47: =CORREL(Raw_Data!M2:M668,Raw_Data!O2:O668) -> 0.99999918 | D47: Predicted Charge | E47: =_xlfn.FORECAST.LINEAR(200,Raw_Data!I2:I668,Raw_Data!G2:G668) -> 34.000586
A48: Intl Minutes Vs Intl Charge | B48: =CORREL(Raw_Data!P2:P668,Raw_Data!R2:R668) -> 0.9999931

Sheet Tests
A1: Churned Day Minutes | C1: Retained Day Minutes | E1: P-Value | G1: Chi_Square test
A2: {=_xlfn._xlws.FILTER(Raw_Data!G2:G668,Raw_Data!T2:T668=TRUE)} -> 129.1 | C2: {=_xlfn._xlws.FILTER(Raw_Data!G2:G668,Raw_Data!T2:T668=FALSE)} -> 184.5 | E2: =_xlfn.T.TEST(_xlfn.ANCHORARRAY(A2),_xlfn.ANCHORARRAY(C2),2,2) -> 2.1022107e-10 | G2: International Plan | I2: yes | J2: no
A3: 332.9 | C3: 110.4 | G3: Churned | I3: =COUNTIFS(Raw_Data!D2:D668,I2,Raw_Data!T2:T668,TRUE) -> 19 | J3: =COUNTIFS(Raw_Data!D2:D668,I2,Raw_Data!T2:T668,FALSE) -> 34
A4: 159.1 | C4: 119.3
A5: 203.4 | C5: 146.3
A6: 251.8 | C6: 211.3
A7: 326.5 | C7: 186.1
A8: 134.4 | C8: 148.8
A9: 62.6 | C9: 193.7
A10: 189.8 | C10: 235.8
A11: 303.9 | C11: 214.1
A12: 172.7 | C12: 179.3
A13: 266.6 | C13: 160.1
A14: 170.4 | C14: 178.3
A15: 296.4 | C15: 135
... A96: 280 | C96: 125.7
C97: 160.4
C98: 169.9
C99: 142.3
C100: 146.2
C101: 231.8
C102: 128.2
C103: 130.2
C104: 209.6
C105: 215.7
C106: 150.7
C107: 161.5
C108: 235.6
... C573: 213.8

Sheet What_If
A1: CHURN WHAT-IF ANALYSIS
A3: Current Customers | B3: =COUNTA(Raw_Data!A2:A668) -> 667
A4: Current Churn Rate | B4: =COUNTIF(Raw_Data!T2:T668,TRUE)/B3 -> 0.14242879
A5: Target Churn Rate | B5: 0.05
A6: Required Churned Customers | B6: =B3*B5 -> 33.35

Sheet Power_Pivot
B4: Row Labels | C4: Sum of Customer service calls | E4: Row Labels | F4: Count of Area code | I4: Row Labels | J4: Sum of Total day calls | K4: Sum of Total day charge | L4: Sum of Total eve minutes | M4: Sum of Total eve calls | N4: Sum of Total eve charge | O4: Sum of Total night minutes | P4: Sum of Total night calls | Q4: Sum of Total night charge | R4: Sum of Total intl minutes | S4: Sum of Total intl calls | T4: Sum of Total intl charge | U4: Sum of Customer service calls
B5: FALSE | C5: 822 | E5: No | F5: 614 | I5: AK | J5: 885 | K5: 260.15 | L5: 1646.6 | M5: 913 | N5: 139.96 | O5: 1715.8 | P5: 845 | Q5: 77.21 | R5: 85.2 | S5: 40 | T5: 23.02 | U5: 16
B6: AK | C6: 16 | E6: FALSE | F6: 538 | I6: AL | J6: 1365 | K6: 416.19 | L6: 2912.3 | M6: 1404 | N6: 247.55 | O6: 2770 | P6: 1208 | Q6: 124.65 | R6: 150.6 | S6: 66 | T6: 40.67 | U6: 15
B7: AL | C7: 14 | E7: TRUE | F7: 76 | I7: AR | J7: 712 | K7: 250.87 | L7: 1513.5 | M7: 691 | N7: 128.65 | O7: 1826.1 | P7: 892 | Q7: 82.18 | R7: 78 | S7: 31 | T7: 21.06 | U7: 8
B8: AR | C8: 8 | E8: Yes | F8: 53 | I8: AZ | J8: 1842 | K8: 537.89 | L8: 3688.5 | M8: 1917 | N8: 313.53 | O8: 3469.6 | P8: 1878 | Q8: 156.13 | R8: 202.7 | S8: 73 | T8: 54.74 | U8: 40
B9: AZ | C9: 36 | E9: FALSE | F9: 34 | I9: CA | J9: 1137 | K9: 323.4 | L9: 1984.7 | M9: 949 | N9: 168.72 | O9: 2146.3 | P9: 970 | Q9: 96.59 | R9: 91.9 | S9: 45 | T9: 24.82 | U9: 16
B10: CA | C10: 9 | E10: TRUE | F10: 19 | I10: CO | J10: 680 | K10: 204.63 | L10: 1348.2 | M10: 803 | N10: 114.59 | O10: 1340.6 | P10: 767 | Q10: 60.32 | R10: 74.6 | S10: 21 | T10: 20.14 | U10: 10
B11: CO | C11: 2 | E11: Grand Total | F11: 667 | I11: CT | J11: 1466 | K11: 455.24 | L11: 3047.8 | M11: 1512 | N11: 259.08 | O11: 3332.7 | P11: 1556 | Q11: 149.98 | R11: 156.7 | S11: 69 | T11: 42.3 | U11: 29
B12: CT | C12: 24 | I12: DC | J12: 1002 | K12: 290.08 | L12: 1702.3 | M12: 920 | N12: 144.69 | O12: 1893.7 | P12: 909 | Q12: 85.21 | R12: 87.5 | S12: 29 | T12: 23.64 | U12: 15
B13: DC | C13: 15 | E13: Row Labels | F13: Sum of Customer service calls | I13: DE | J13: 991 | K13: 305.89 | L13: 2007.8 | M13: 873 | N13: 170.66 | O13: 1987.9 | P13: 987 | Q13: 89.46 | R13: 99.5 | S13: 63 | T13: 26.89 | U13: 12
B14: DE | C14: 12 | E14: FALSE | F14: 822 | I14: FL | J14: 1005 | K14: 283.45 | L14: 2115.7 | M14: 1088 | N14: 179.83 | O14: 1788 | P14: 881 | Q14: 80.47 | R14: 96.3 | S14: 38 | T14: 26 | U14: 12
B15: FL | C15: 11 | E15: TRUE | F15: 221 | I15: GA | J15: 439 | K15: 145.1 | L15: 1014.2 | M15: 618 | N15: 86.21 | O15: 876.8 | P15: 509 | Q15: 39.45 | R15: 47.4 | S15: 21 | T15: 12.8 | U15: 10
B16: GA | C16: 10 | E16: Grand Total | F16: 1043 | I16: HI | J16: 1005 | K16: 293.63 | L16: 1740.7 | M16: 877 | N16: 147.96 | O16: 1957.1 | P16: 930 | Q16: 88.07 | R16: 89.7 | S16: 35 | T16: 24.23 | U16: 6
B17: HI | C17: 6 | I17: IA | J17: 577 | K17: 151.41 | L17: 1384.9 | M17: 650 | N17: 117.71 | O17: 1080.8 | P17: 654 | Q17: 48.64 | R17: 55.2 | S17: 27 | T17: 14.92 | U17: 9
B18: IA | C18: 9 | E18: Row Labels | I18: ID | J18: 1705 | K18: 556.01 | L18: 3306.5 | M18: 1800 | N18: 281.04 | O18: 3288.7 | P18: 1709 | Q18: 147.99 | R18: 185.8 | S18: 92 | T18: 50.18 | U18: 30
B19: ID | C19: 20 | E19: High Contact | I19: IL | J19: 1351 | K19: 411.4 | L19: 2296.5 | M19: 1253 | N19: 195.2 | O19: 2492.5 | P19: 1376 | Q19: 112.16 | R19: 136.4 | S19: 57 | T19: 36.85 | U19: 16
B20: IL | C20: 15 | E20: Churned | I20: IN | J20: 1887 | K20: 564.25 | L20: 3616.3 | M20: 1624 | N20: 307.38 | O20: 3330.4 | P20: 1816 | Q20: 149.87 | R20: 181.9 | S20: 74 | T20: 49.11 | U20: 33
B21: IN | C21: 21 | E21: Retained | I21: KS | J21: 1856 | K21: 545.31 | L21: 3624.2 | M21: 1994 | N21: 308.05 | O21: 3602.5 | P21: 1712 | Q21: 162.12 | R21: 192.3 | S21: 89 | T21: 51.92 | U21: 20
B22: KS | C22: 15 | E22: Low Contact | I22: KY | J22: 1659 | K22: 460.29 | L22: 3218.9 | M22: 1511 | N22: 273.62 | O22: 3130 | P22: 1583 | Q22: 140.84 | R22: 162 | S22: 74 | T22: 43.74 | U22: 26
B23: KY | C23: 19 | E23: Churned | I23: LA | J23: 1675 | K23: 525.5 | L23: 3305.7 | M23: 1546 | N23: 280.99 | O23: 3058.1 | P23: 1522 | Q23: 137.62 | R23: 155.7 | S23: 85 | T23: 42.04 | U23: 27
B24: LA | C24: 27 | E24: Retained | I24: MA | J24: 1365 | K24: 427.39 | L24: 2708.2 | M24: 1272 | N24: 230.21 | O24: 2265.7 | P24: 1249 | Q24: 101.96 | R24: 122.2 | S24: 66 | T24: 32.99 | U24: 15
B25: MA | C25: 10 | E25: Normal Contact | I25: MD | J25: 1085 | K25: 321.15 | L25: 2059.4 | M25: 909 | N25: 175.07 | O25: 1817.4 | P25: 967 | Q25: 81.77 | R25: 118.7 | S25: 47 | T25: 32.05 | U25: 20
B26: MD | C26: 14 | E26: Churned | I26: ME | J26: 1244 | K26: 432.82 | L26: 2575.6 | M26: 1274 | N26: 218.93 | O26: 2531.1 | P26: 1368 | Q26: 113.9 | R26: 131.7 | S26: 58 | T26: 35.57 | U26: 23
B27: ME | C27: 19 | E27: Retained | I27: MI | J27: 1641 | K27: 475.81 | L27: 3085.5 | M27: 1596 | N27: 262.28 | O27: 2823.9 | P27: 1483 | Q27: 127.07 | R27: 160.6 | S27: 65 | T27: 43.36 | U27: 27
B28: MI | C28: 19 | E28: Grand Total | I28: MN | J28: 1403 | K28: 480.99 | L28: 2831.1 | M28: 1292 | N28: 240.64 | O28: 3056.5 | P28: 1464 | Q28: 137.54 | R28: 148.2 | S28: 54 | T28: 40.02 | U28: 24
B29: MN | C29: 19 | I29: MO | J29: 1202 | K29: 351.37 | L29: 2215.4 | M29: 1149 | N29: 188.3 | O29: 2718.7 | P29: 1210 | Q29: 122.34 | R29: 115 | S29: 57 | T29: 31.05 | U29: 20
B30: MO | C30: 12 | I30: MS | J30: 1630 | K30: 550.79 | L30: 3545.9 | M30: 1756 | N30: 301.4 | O30: 3397 | P30: 1768 | Q30: 152.85 | R30: 193.5 | S30: 59 | T30: 52.26 | U30: 29
B31: MS | C31: 19 | I31: MT | J31: 1424 | K31: 448.09 | L31: 3141.5 | M31: 1480 | N31: 267.03 | O31: 2967.9 | P31: 1527 | Q31: 133.54 | R31: 155.2 | S31: 75 | T31: 41.91 | U31: 27
B32: MT | C32: 16 | I32: NC | J32: 1215 | K32: 374.4 | L32: 2579.7 | M32: 1231 | N32: 219.3 | O32: 2527.2 | P32: 1208 | Q32: 113.73 | R32: 117 | S32: 61 | T32: 31.59 | U32: 20
B33: NC | C33: 13 | I33: ND | J33: 1782 | K33: 581.52 | L33: 3978.2 | M33: 2023 | N33: 338.14 | O33: 3492 | P33: 1825 | Q33: 157.16 | R33: 188 | S33: 79 | T33: 50.78 | U33: 24
B34: ND | C34: 23 | I34: NE | J34: 1681 | K34: 475.92 | L34: 3306.1 | M34: 1720 | N34: 281.02 | O34: 3288.1 | P34: 1545 | Q34: 147.97 | R34: 154.6 | S34: 72 | T34: 41.76 | U34: 16
B35: NE | C35: 15 | I35: NH | J35: 1195 | K35: 390.49 | L35: 2590 | M35: 1235 | N35: 220.14 | O35: 2516.9 | P35: 1187 | Q35: 113.27 | R35: 118.1 | S35: 49 | T35: 31.91 | U35: 15
B36: NH | C36: 15 | I36: NJ | J36: 1839 | K36: 576.15 | L36: 3490.8 | M36: 1965 | N36: 296.73 | O36: 3836 | P36: 1791 | Q36: 172.61 | R36: 173.8 | S36: 79 | T36: 46.92 | U36: 29
B37: NJ | C37: 21 | I37: NM | J37: 1865 | K37: 507.7 | L37: 3816.9 | M37: 1882 | N37: 324.43 | O37: 3512.4 | P37: 1719 | Q37: 158.06 | R37: 194.2 | S37: 89 | T37: 52.47 | U37: 35
B38: NM | C38: 27 | I38: NV | J38: 453 | K38: 136.22 | L38: 970.5 | M38: 502 | N38: 82.49 | O38: 1068.1 | P38: 506 | Q38: 48.06 | R38: 47.6 | S38: 29 | T38: 12.85 | U38: 7
B39: NV | C39: 6 | I39: NY | J39: 1410 | K39: 474.6 | L39: 2960.7 | M39: 1440 | N39: 251.65 | O39: 2990.8 | P39: 1544 | Q39: 134.6 | R39: 134.1 | S39: 61 | T39: 36.21 | U39: 27
B40: NY | C40: 18 | I40: OH | J40: 1185 | K40: 358.01 | L40: 2453 | M40: 1204 | N40: 208.51 | O40: 2200.8 | P40: 1206 | Q40: 99.04 | R40: 122.9 | S40: 48 | T40: 33.19 | U40: 17
... B56: WY | C56: 16 | I56: Grand Total | J56: 67325 | K56: 20518.1 | L56: 135638 | M56: 67018 | N56: 11529.27 | O56: 133190.1 | P56: 66776 | Q56: 5993.6 | R56: 6829 | S56: 3020 | T56: 1844.22 | U56: 1043
B57: TRUE | C57: 221
B58: AL | C58: 1
...

Sheet Dashboard
