Workbook
Name Slicer_Species: #N/A

Sheet RAW_DATA
A1: sepal_length | B1: sepal_width | C1: petal_length | D1: petal_width | E1: species
A2: 5.1 | B2: 3.5 | C2: 1.4 | D2: 0.2 | E2: setosa
A3: 4.9 | B3: 3 | C3: 1.4 | D3: 0.2 | E3: setosa
A4: 4.7 | B4: 3.2 | C4: 1.3 | D4: 0.2 | E4: setosa
A5: 4.6 | B5: 3.1 | C5: 1.5 | D5: 0.2 | E5: setosa
A6: 5 | B6: 3.6 | C6: 1.4 | D6: 0.2 | E6: setosa
A7: 5.4 | B7: 3.9 | C7: 1.7 | D7: 0.4 | E7: setosa
A8: 4.6 | B8: 3.4 | C8: 1.4 | D8: 0.3 | E8: setosa
A9: 5 | B9: 3.4 | C9: 1.5 | D9: 0.2 | E9: setosa
A10: 4.4 | B10: 2.9 | C10: 1.4 | D10: 0.2 | E10: setosa
A11: 4.9 | B11: 3.1 | C11: 1.5 | D11: 0.1 | E11: setosa
A12: 5.4 | B12: 3.7 | C12: 1.5 | D12: 0.2 | E12: setosa
A13: 4.8 | B13: 3.4 | C13: 1.6 | D13: 0.2 | E13: setosa
... A151: 5.9 | B151: 3 | C151: 5.1 | D151: 1.8 | E151: virginica

Sheet LOGICAL
A1: sepal_length | B1: species | C1: IF CLASSIFICATION | D1: IFS CLASSIFICATION | E1: AND TEST | F1: OR TEST | G1: NOT TEST | H1: NESTED IF | I1: CHOOSE | J1: SWITCH | K1: ISERROR | L1: ISBLANK | M1: ISNUMBER
A2: =RAW_DATA!A2 -> 5.1 | B2: =RAW_DATA!E2 -> setosa | C2: =IF(A2>=5,"LONG","SHORT") -> LONG | D2: {=_xlfn.IFS(A2<5,"Short",A2<6,"Medium",A2>=6,"Long")} -> Medium | E2: =IF(AND(RAW_DATA!C2>4,RAW_DATA!D2>1.5),"Large Petals","Not Large") -> Not Large | F2: =IF(OR(RAW_DATA!A2>6,RAW_DATA!C2>4),"Large Flower","Normal Flower") -> Normal Flower | G2: =IF(NOT(B2="setosa"),"Not Setosa","Setosa") -> Setosa | H2: =IF(A2<5,"Small",IF(A2<6,"Medium","Large")) -> Medium | I2: =CHOOSE(MATCH(B2,{"setosa","versicolor","virginica"},0),"Setosa","Versicolor","Virginica") -> Setosa | J2: {=_xlfn.SWITCH(B2,"setosa","Setosa Flower","versicolor","Versicolor Flower","virginica","Virginica Flower","Unknown")} -> Setosa Flower | K2: =IF(ISERROR(A2/0),"Error","Valid") -> Error | L2: =IF(ISBLANK(A2),"Missing","Available") -> Available | M2: =IF(ISNUMBER(A2),"Numeric","Not Numeric") -> Numeric
A3: =RAW_DATA!A3 -> 4.9 | B3: =RAW_DATA!E3 -> setosa | C3: =IF(A3>=5,"LONG","SHORT") -> SHORT | D3: {=_xlfn.IFS(A3<5,"Short",A3<6,"Medium",A3>=6,"Long")} -> Short | E3: =IF(AND(RAW_DATA!C3>4,RAW_DATA!D3>1.5),"Large Petals","Not Large") -> Not Large | F3: =IF(OR(RAW_DATA!A3>6,RAW_DATA!C3>4),"Large Flower","Normal Flower") -> Normal Flower | G3: =IF(NOT(B3="setosa"),"Not Setosa","Setosa") -> Setosa | H3: =IF(A3<5,"Small",IF(A3<6,"Medium","Large")) -> Small | I3: =CHOOSE(MATCH(B3,{"setosa","versicolor","virginica"},0),"Setosa","Versicolor","Virginica") -> Setosa | J3: {=_xlfn.SWITCH(B3,"setosa","Setosa Flower","versicolor","Versicolor Flower","virginica","Virginica Flower","Unknown")} -> Setosa Flower | K3: =IF(ISERROR(A3/0),"Error","Valid") -> Error | L3: =IF(ISBLANK(A3),"Missing","Available") -> Available | M3: =IF(ISNUMBER(A3),"Numeric","Not Numeric") -> Numeric
A4: =RAW_DATA!A4 -> 4.7 | B4: =RAW_DATA!E4 -> setosa | C4: =IF(A4>=5,"LONG","SHORT") -> SHORT | D4: {=_xlfn.IFS(A4<5,"Short",A4<6,"Medium",A4>=6,"Long")} -> Short | E4: =IF(AND(RAW_DATA!C4>4,RAW_DATA!D4>1.5),"Large Petals","Not Large") -> Not Large | F4: =IF(OR(RAW_DATA!A4>6,RAW_DATA!C4>4),"Large Flower","Normal Flower") -> Normal Flower | G4: =IF(NOT(B4="setosa"),"Not Setosa","Setosa") -> Setosa | H4: =IF(A4<5,"Small",IF(A4<6,"Medium","Large")) -> Small | I4: =CHOOSE(MATCH(B4,{"setosa","versicolor","virginica"},0),"Setosa","Versicolor","Virginica") -> Setosa | J4: {=_xlfn.SWITCH(B4,"setosa","Setosa Flower","versicolor","Versicolor Flower","virginica","Virginica Flower","Unknown")} -> Setosa Flower | K4: =IF(ISERROR(A4/0),"Error","Valid") -> Error | L4: =IF(ISBLANK(A4),"Missing","Available") -> Available | M4: =IF(ISNUMBER(A4),"Numeric","Not Numeric") -> Numeric
A5: =RAW_DATA!A5 -> 4.6 | B5: =RAW_DATA!E5 -> setosa | C5: =IF(A5>=5,"LONG","SHORT") -> SHORT | D5: {=_xlfn.IFS(A5<5,"Short",A5<6,"Medium",A5>=6,"Long")} -> Short | E5: =IF(AND(RAW_DATA!C5>4,RAW_DATA!D5>1.5),"Large Petals","Not Large") -> Not Large | F5: =IF(OR(RAW_DATA!A5>6,RAW_DATA!C5>4),"Large Flower","Normal Flower") -> Normal Flower | G5: =IF(NOT(B5="setosa"),"Not Setosa","Setosa") -> Setosa | H5: =IF(A5<5,"Small",IF(A5<6,"Medium","Large")) -> Small | I5: =CHOOSE(MATCH(B5,{"setosa","versicolor","virginica"},0),"Setosa","Versicolor","Virginica") -> Setosa | J5: {=_xlfn.SWITCH(B5,"setosa","Setosa Flower","versicolor","Versicolor Flower","virginica","Virginica Flower","Unknown")} -> Setosa Flower | K5: =IF(ISERROR(A5/0),"Error","Valid") -> Error | L5: =IF(ISBLANK(A5),"Missing","Available") -> Available | M5: =IF(ISNUMBER(A5),"Numeric","Not Numeric") -> Numeric
A6: =RAW_DATA!A6 -> 5 | B6: =RAW_DATA!E6 -> setosa | C6: =IF(A6>=5,"LONG","SHORT") -> LONG | D6: {=_xlfn.IFS(A6<5,"Short",A6<6,"Medium",A6>=6,"Long")} -> Medium | E6: =IF(AND(RAW_DATA!C6>4,RAW_DATA!D6>1.5),"Large Petals","Not Large") -> Not Large | F6: =IF(OR(RAW_DATA!A6>6,RAW_DATA!C6>4),"Large Flower","Normal Flower") -> Normal Flower | G6: =IF(NOT(B6="setosa"),"Not Setosa","Setosa") -> Setosa | H6: =IF(A6<5,"Small",IF(A6<6,"Medium","Large")) -> Medium | I6: =CHOOSE(MATCH(B6,{"setosa","versicolor","virginica"},0),"Setosa","Versicolor","Virginica") -> Setosa | J6: {=_xlfn.SWITCH(B6,"setosa","Setosa Flower","versicolor","Versicolor Flower","virginica","Virginica Flower","Unknown")} -> Setosa Flower | K6: =IF(ISERROR(A6/0),"Error","Valid") -> Error | L6: =IF(ISBLANK(A6),"Missing","Available") -> Available | M6: =IF(ISNUMBER(A6),"Numeric","Not Numeric") -> Numeric
A7: =RAW_DATA!A7 -> 5.4 | B7: =RAW_DATA!E7 -> setosa | C7: =IF(A7>=5,"LONG","SHORT") -> LONG | D7: {=_xlfn.IFS(A7<5,"Short",A7<6,"Medium",A7>=6,"Long")} -> Medium | E7: =IF(AND(RAW_DATA!C7>4,RAW_DATA!D7>1.5),"Large Petals","Not Large") -> Not Large | F7: =IF(OR(RAW_DATA!A7>6,RAW_DATA!C7>4),"Large Flower","Normal Flower") -> Normal Flower | G7: =IF(NOT(B7="setosa"),"Not Setosa","Setosa") -> Setosa | H7: =IF(A7<5,"Small",IF(A7<6,"Medium","Large")) -> Medium | I7: =CHOOSE(MATCH(B7,{"setosa","versicolor","virginica"},0),"Setosa","Versicolor","Virginica") -> Setosa | J7: {=_xlfn.SWITCH(B7,"setosa","Setosa Flower","versicolor","Versicolor Flower","virginica","Virginica Flower","Unknown")} -> Setosa Flower | K7: =IF(ISERROR(A7/0),"Error","Valid") -> Error | L7: =IF(ISBLANK(A7),"Missing","Available") -> Available | M7: =IF(ISNUMBER(A7),"Numeric","Not Numeric") -> Numeric
A8: =RAW_DATA!A8 -> 4.6 | B8: =RAW_DATA!E8 -> setosa | C8: =IF(A8>=5,"LONG","SHORT") -> SHORT | D8: {=_xlfn.IFS(A8<5,"Short",A8<6,"Medium",A8>=6,"Long")} -> Short | E8: =IF(AND(RAW_DATA!C8>4,RAW_DATA!D8>1.5),"Large Petals","Not Large") -> Not Large | F8: =IF(OR(RAW_DATA!A8>6,RAW_DATA!C8>4),"Large Flower","Normal Flower") -> Normal Flower | G8: =IF(NOT(B8="setosa"),"Not Setosa","Setosa") -> Setosa | H8: =IF(A8<5,"Small",IF(A8<6,"Medium","Large")) -> Small | I8: =CHOOSE(MATCH(B8,{"setosa","versicolor","virginica"},0),"Setosa","Versicolor","Virginica") -> Setosa | J8: {=_xlfn.SWITCH(B8,"setosa","Setosa Flower","versicolor","Versicolor Flower","virginica","Virginica Flower","Unknown")} -> Setosa Flower | K8: =IF(ISERROR(A8/0),"Error","Valid") -> Error | L8: =IF(ISBLANK(A8),"Missing","Available") -> Available | M8: =IF(ISNUMBER(A8),"Numeric","Not Numeric") -> Numeric
A9: =RAW_DATA!A9 -> 5 | B9: =RAW_DATA!E9 -> setosa | C9: =IF(A9>=5,"LONG","SHORT") -> LONG | D9: {=_xlfn.IFS(A9<5,"Short",A9<6,"Medium",A9>=6,"Long")} -> Medium | E9: =IF(AND(RAW_DATA!C9>4,RAW_DATA!D9>1.5),"Large Petals","Not Large") -> Not Large | F9: =IF(OR(RAW_DATA!A9>6,RAW_DATA!C9>4),"Large Flower","Normal Flower") -> Normal Flower | G9: =IF(NOT(B9="setosa"),"Not Setosa","Setosa") -> Setosa | H9: =IF(A9<5,"Small",IF(A9<6,"Medium","Large")) -> Medium | I9: =CHOOSE(MATCH(B9,{"setosa","versicolor","virginica"},0),"Setosa","Versicolor","Virginica") -> Setosa | J9: {=_xlfn.SWITCH(B9,"setosa","Setosa Flower","versicolor","Versicolor Flower","virginica","Virginica Flower","Unknown")} -> Setosa Flower | K9: =IF(ISERROR(A9/0),"Error","Valid") -> Error | L9: =IF(ISBLANK(A9),"Missing","Available") -> Available | M9: =IF(ISNUMBER(A9),"Numeric","Not Numeric") -> Numeric
A10: =RAW_DATA!A10 -> 4.4 | B10: =RAW_DATA!E10 -> setosa | C10: =IF(A10>=5,"LONG","SHORT") -> SHORT | D10: {=_xlfn.IFS(A10<5,"Short",A10<6,"Medium",A10>=6,"Long")} -> Short | E10: =IF(AND(RAW_DATA!C10>4,RAW_DATA!D10>1.5),"Large Petals","Not Large") -> Not Large | F10: =IF(OR(RAW_DATA!A10>6,RAW_DATA!C10>4),"Large Flower","Normal Flower") -> Normal Flower | G10: =IF(NOT(B10="setosa"),"Not Setosa","Setosa") -> Setosa | H10: =IF(A10<5,"Small",IF(A10<6,"Medium","Large")) -> Small | I10: =CHOOSE(MATCH(B10,{"setosa","versicolor","virginica"},0),"Setosa","Versicolor","Virginica") -> Setosa | J10: {=_xlfn.SWITCH(B10,"setosa","Setosa Flower","versicolor","Versicolor Flower","virginica","Virginica Flower","Unknown")} -> Setosa Flower | K10: =IF(ISERROR(A10/0),"Error","Valid") -> Error | L10: =IF(ISBLANK(A10),"Missing","Available") -> Available | M10: =IF(ISNUMBER(A10),"Numeric","Not Numeric") -> Numeric
A11: =RAW_DATA!A11 -> 4.9 | B11: =RAW_DATA!E11 -> setosa | C11: =IF(A11>=5,"LONG","SHORT") -> SHORT | D11: {=_xlfn.IFS(A11<5,"Short",A11<6,"Medium",A11>=6,"Long")} -> Short | E11: =IF(AND(RAW_DATA!C11>4,RAW_DATA!D11>1.5),"Large Petals","Not Large") -> Not Large | F11: =IF(OR(RAW_DATA!A11>6,RAW_DATA!C11>4),"Large Flower","Normal Flower") -> Normal Flower | G11: =IF(NOT(B11="setosa"),"Not Setosa","Setosa") -> Setosa | H11: =IF(A11<5,"Small",IF(A11<6,"Medium","Large")) -> Small | I11: =CHOOSE(MATCH(B11,{"setosa","versicolor","virginica"},0),"Setosa","Versicolor","Virginica") -> Setosa | J11: {=_xlfn.SWITCH(B11,"setosa","Setosa Flower","versicolor","Versicolor Flower","virginica","Virginica Flower","Unknown")} -> Setosa Flower | K11: =IF(ISERROR(A11/0),"Error","Valid") -> Error | L11: =IF(ISBLANK(A11),"Missing","Available") -> Available | M11: =IF(ISNUMBER(A11),"Numeric","Not Numeric") -> Numeric
A12: =RAW_DATA!A12 -> 5.4 | B12: =RAW_DATA!E12 -> setosa | C12: =IF(A12>=5,"LONG","SHORT") -> LONG | D12: {=_xlfn.IFS(A12<5,"Short",A12<6,"Medium",A12>=6,"Long")} -> Medium | E12: =IF(AND(RAW_DATA!C12>4,RAW_DATA!D12>1.5),"Large Petals","Not Large") -> Not Large | F12: =IF(OR(RAW_DATA!A12>6,RAW_DATA!C12>4),"Large Flower","Normal Flower") -> Normal Flower | G12: =IF(NOT(B12="setosa"),"Not Setosa","Setosa") -> Setosa | H12: =IF(A12<5,"Small",IF(A12<6,"Medium","Large")) -> Medium | I12: =CHOOSE(MATCH(B12,{"setosa","versicolor","virginica"},0),"Setosa","Versicolor","Virginica") -> Setosa | J12: {=_xlfn.SWITCH(B12,"setosa","Setosa Flower","versicolor","Versicolor Flower","virginica","Virginica Flower","Unknown")} -> Setosa Flower | K12: =IF(ISERROR(A12/0),"Error","Valid") -> Error | L12: =IF(ISBLANK(A12),"Missing","Available") -> Available | M12: =IF(ISNUMBER(A12),"Numeric","Not Numeric") -> Numeric
A13: =RAW_DATA!A13 -> 4.8 | B13: =RAW_DATA!E13 -> setosa | C13: =IF(A13>=5,"LONG","SHORT") -> SHORT | D13: {=_xlfn.IFS(A13<5,"Short",A13<6,"Medium",A13>=6,"Long")} -> Short | E13: =IF(AND(RAW_DATA!C13>4,RAW_DATA!D13>1.5),"Large Petals","Not Large") -> Not Large | F13: =IF(OR(RAW_DATA!A13>6,RAW_DATA!C13>4),"Large Flower","Normal Flower") -> Normal Flower | G13: =IF(NOT(B13="setosa"),"Not Setosa","Setosa") -> Setosa | H13: =IF(A13<5,"Small",IF(A13<6,"Medium","Large")) -> Small | I13: =CHOOSE(MATCH(B13,{"setosa","versicolor","virginica"},0),"Setosa","Versicolor","Virginica") -> Setosa | J13: {=_xlfn.SWITCH(B13,"setosa","Setosa Flower","versicolor","Versicolor Flower","virginica","Virginica Flower","Unknown")} -> Setosa Flower | K13: =IF(ISERROR(A13/0),"Error","Valid") -> Error | L13: =IF(ISBLANK(A13),"Missing","Available") -> Available | M13: =IF(ISNUMBER(A13),"Numeric","Not Numeric") -> Numeric
... A151: =RAW_DATA!A151 -> 5.9 | B151: =RAW_DATA!E151 -> virginica | C151: =IF(A151>=5,"LONG","SHORT") -> LONG | D151: {=_xlfn.IFS(A151<5,"Short",A151<6,"Medium",A151>=6,"Long")} -> Medium | E151: =IF(AND(RAW_DATA!C151>4,RAW_DATA!D151>1.5),"Large Petals","Not Large") -> Large Petals | F151: =IF(OR(RAW_DATA!A151>6,RAW_DATA!C151>4),"Large Flower","Normal Flower") -> Large Flower | G151: =IF(NOT(B151="setosa"),"Not Setosa","Setosa") -> Not Setosa | H151: =IF(A151<5,"Small",IF(A151<6,"Medium","Large")) -> Medium | I151: =CHOOSE(MATCH(B151,{"setosa","versicolor","virginica"},0),"Setosa","Versicolor","Virginica") -> Virginica | J151: {=_xlfn.SWITCH(B151,"setosa","Setosa Flower","versicolor","Versicolor Flower","virginica","Virginica Flower","Unknown")} -> Virginica Flower | K151: =IF(ISERROR(A151/0),"Error","Valid") -> Error | L151: =IF(ISBLANK(A151),"Missing","Available") -> Available | M151: =IF(ISNUMBER(A151),"Numeric","Not Numeric") -> Numeric

Sheet LOOKUPS
A1: Species | B1: Code | D1: test species | E1: Vlookup | F1: Xlookup | G1: Index-match | H1: Hlookup | J1: setosa | K1: versicolor | L1: virginica
A2: setosa | B2: 1 | D2: setosa | E2: =VLOOKUP(D2,$A$2:$B$4,2,FALSE) -> 1 | F2: =_xlfn.XLOOKUP(D2,$A$2:$A$4,$B$2:$B$4,"Not Found") -> 1 | G2: =INDEX($B$2:$B$4,MATCH(D2,$A$2:$A$4,0)) -> 1 | H2: =HLOOKUP(D2,$J$1:$L$2,2,FALSE) -> 1 | J2: 1 | K2: 2 | L2: 3
A3: versicolor | B3: 2
A4: virginica | B4: 3
D5: Largest Petal Length | E5: =MAX(RAW_DATA!C2:C151) -> 6.9
D6: Smallest Petal Length | E6: =MIN(RAW_DATA!C2:C151) -> 1
D7: Largest Petal Species | E7: =_xlfn.XLOOKUP(MAX(RAW_DATA!C2:C151),RAW_DATA!C2:C151,RAW_DATA!E2:E151) -> virginica
D8: Smallest Petal Species | E8: =_xlfn.XLOOKUP(MIN(RAW_DATA!C2:C151),RAW_DATA!C2:C151,RAW_DATA!E2:E151) -> setosa
D12: INDIRECT | E12: {=INDIRECT("A"&ROW())} -> 0
D13: OFFSET | E13: =OFFSET(RAW_DATA!A2,0,2) -> 1.4
D14: Dynamic Species | E14: {=INDIRECT("Raw_Data!E"&ROW())} -> setosa

Sheet ARRAYS
A1: Dynamic array anlysis
A3: Unique species | C3: Filtered setosa | E3: Petal lenth>5 | I3: {=TRANSPOSE(RAW_DATA!A2:A6)} -> 5.1 | J3: 4.9 | K3: 4.7 | L3: 4.6 | M3: 5
A4: {=_xlfn.UNIQUE(RAW_DATA!E2:E151)} -> setosa | E4: {=_xlfn._xlws.FILTER(RAW_DATA!A2:E151,RAW_DATA!C2:C151>5)} -> 6 | F4: 2.7 | G4: 5.1 | H4: 1.6 | I4: versicolor | R4: Sequence
A5: versicolor | E5: 6.3 | F5: 3.3 | G5: 6 | H5: 2.5 | I5: virginica | L5: {=_xlfn._xlws.FILTER([1]I4RAW_DATA!A2:E151,RAW_DATA!E2:E151="setosa")} -> #REF! | M5: #REF! | N5: #REF! | O5: #REF! | P5: #REF! | R5: {=_xlfn.SEQUENCE(150)} -> 1 | T5: SUMPRODUCT Analysis
A6: virginica | E6: 5.8 | F6: 2.7 | G6: 5.1 | H6: 1.9 | I6: virginica | L6: #REF! | M6: #REF! | N6: #REF! | O6: #REF! | P6: #REF! | R6: 2 | T6: Setosa Count | U6: {=SUMPRODUCT(--(RAW_DATA!E2:E151="setosa"))} -> 50
E7: 7.1 | F7: 3 | G7: 5.9 | H7: 2.1 | I7: virginica | L7: #REF! | M7: #REF! | N7: #REF! | O7: #REF! | P7: #REF! | R7: 3 | T7: Setosa Petal Length Total | U7: {=SUMPRODUCT((RAW_DATA!E2:E151="setosa")*RAW_DATA!C2:C151)} -> 73.2
A8: sorted sepal length | E8: 6.3 | F8: 2.9 | G8: 5.6 | H8: 1.8 | I8: virginica | L8: #REF! | M8: #REF! | N8: #REF! | O8: #REF! | P8: #REF! | R8: 4 | T8: Virginica Petal Width Tota | U8: {=SUMPRODUCT((RAW_DATA!E2:E151="setosa")*RAW_DATA!C2:C151)} -> 73.2
A9: {=_xlfn._xlws.SORT(RAW_DATA!A2:A151)} -> 4.3 | E9: 6.5 | F9: 3 | G9: 5.8 | H9: 2.2 | I9: virginica | L9: #REF! | M9: #REF! | N9: #REF! | O9: #REF! | P9: #REF! | R9: 5
A10: 4.4 | E10: 7.6 | F10: 3 | G10: 6.6 | H10: 2.1 | I10: virginica | L10: #REF! | M10: #REF! | N10: #REF! | O10: #REF! | P10: #REF! | R10: 6
A11: 4.4 | E11: 7.3 | F11: 2.9 | G11: 6.3 | H11: 1.8 | I11: virginica | L11: #REF! | M11: #REF! | N11: #REF! | O11: #REF! | P11: #REF! | R11: 7
A12: 4.4 | E12: 6.7 | F12: 2.5 | G12: 5.8 | H12: 1.8 | I12: virginica | L12: #REF! | M12: #REF! | N12: #REF! | O12: #REF! | P12: #REF! | R12: 8
A13: 4.5 | E13: 7.2 | F13: 3.6 | G13: 6.1 | H13: 2.5 | I13: virginica | L13: #REF! | M13: #REF! | N13: #REF! | O13: #REF! | P13: #REF! | R13: 9
A14: 4.6 | E14: 6.5 | F14: 3.2 | G14: 5.1 | H14: 2 | I14: virginica | L14: #REF! | M14: #REF! | N14: #REF! | O14: #REF! | P14: #REF! | R14: 10
A15: 4.6 | E15: 6.4 | F15: 2.7 | G15: 5.3 | H15: 1.9 | I15: virginica | L15: #REF! | M15: #REF! | N15: #REF! | O15: #REF! | P15: #REF! | R15: 11
A16: 4.6 | E16: 6.8 | F16: 3 | G16: 5.5 | H16: 2.1 | I16: virginica | L16: #REF! | M16: #REF! | N16: #REF! | O16: #REF! | P16: #REF! | R16: 12
A17: 4.6 | E17: 5.8 | F17: 2.8 | G17: 5.1 | H17: 2.4 | I17: virginica | L17: #REF! | M17: #REF! | N17: #REF! | O17: #REF! | P17: #REF! | R17: 13
A18: 4.7 | E18: 6.4 | F18: 3.2 | G18: 5.3 | H18: 2.3 | I18: virginica | L18: #REF! | M18: #REF! | N18: #REF! | O18: #REF! | P18: #REF! | R18: 14
A19: 4.7 | E19: 6.5 | F19: 3 | G19: 5.5 | H19: 1.8 | I19: virginica | L19: #REF! | M19: #REF! | N19: #REF! | O19: #REF! | P19: #REF! | R19: 15
A20: 4.8 | E20: 7.7 | F20: 3.8 | G20: 6.7 | H20: 2.2 | I20: virginica | L20: #REF! | M20: #REF! | N20: #REF! | O20: #REF! | P20: #REF! | R20: 16
A21: 4.8 | E21: 7.7 | F21: 2.6 | G21: 6.9 | H21: 2.3 | I21: virginica | L21: #REF! | M21: #REF! | N21: #REF! | O21: #REF! | P21: #REF! | R21: 17
... A45: 5.1 | E45: 5.9 | F45: 3 | G45: 5.1 | H45: 1.8 | I45: virginica | L45: #REF! | M45: #REF! | N45: #REF! | O45: #REF! | P45: #REF! | R45: 41
A46: 5.1 | L46: #REF! | M46: #REF! | N46: #REF! | O46: #REF! | P46: #REF! | R46: 42
A47: 5.1 | L47: #REF! | M47: #REF! | N47: #REF! | O47: #REF! | P47: #REF! | R47: 43
A48: 5.1 | L48: #REF! | M48: #REF! | N48: #REF! | O48: #REF! | P48: #REF! | R48: 44
A49: 5.1 | L49: #REF! | M49: #REF! | N49: #REF! | O49: #REF! | P49: #REF! | R49: 45
A50: 5.2 | L50: #REF! | M50: #REF! | N50: #REF! | O50: #REF! | P50: #REF! | R50: 46
A51: 5.2 | L51: #REF! | M51: #REF! | N51: #REF! | O51: #REF! | P51: #REF! | R51: 47
A52: 5.2 | L52: #REF! | M52: #REF! | N52: #REF! | O52: #REF! | P52: #REF! | R52: 48
A53: 5.2 | L53: #REF! | M53: #REF! | N53: #REF! | O53: #REF! | P53: #REF! | R53: 49
A54: 5.3 | L54: #REF! | M54: #REF! | N54: #REF! | O54: #REF! | P54: #REF! | R54: 50
A55: 5.4 | R55: 51
A56: 5.4 | R56: 52
A57: 5.4 | R57: 53
A58: 5.4 | R58: 54
A59: 5.4 | R59: 55
A60: 5.4 | R60: 56
A61: 5.5 | R61: 57
A62: 5.5 | R62: 58
A63: 5.5 | R63: 59
A64: 5.5 | R64: 60
...

Sheet CLEANING
A1: Original Species | B1: TRIM | C1: CLEAN | D1: TRIM + CLEAN | E1: SUBSTITUTE | F1: Blank Check | G1: Duplicate Check
A2: =RAW_DATA!E2 -> setosa | B2: =TRIM(A2) -> setosa | C2: =CLEAN(A2) -> setosa | D2: =TRIM(CLEAN(A2)) -> setosa | E2: =SUBSTITUTE(D2,"setosa","Setosa") -> Setosa | F2: =IF(ISBLANK(A2),"Missing","Complete") -> Complete | G2: =IF(COUNTIF($A$2:A2,A2)>1,"Duplicate","Unique") -> Unique
A3: =RAW_DATA!E3 -> setosa | B3: =TRIM(A3) -> setosa | C3: =CLEAN(A3) -> setosa | D3: =TRIM(CLEAN(A3)) -> setosa | E3: =SUBSTITUTE(D3,"setosa","Setosa") -> Setosa | F3: =IF(ISBLANK(A3),"Missing","Complete") -> Complete | G3: =IF(COUNTIF($A$2:A3,A3)>1,"Duplicate","Unique") -> Duplicate
A4: =RAW_DATA!E4 -> setosa | B4: =TRIM(A4) -> setosa | C4: =CLEAN(A4) -> setosa | D4: =TRIM(CLEAN(A4)) -> setosa | E4: =SUBSTITUTE(D4,"setosa","Setosa") -> Setosa | F4: =IF(ISBLANK(A4),"Missing","Complete") -> Complete | G4: =IF(COUNTIF($A$2:A4,A4)>1,"Duplicate","Unique") -> Duplicate
A5: =RAW_DATA!E5 -> setosa | B5: =TRIM(A5) -> setosa | C5: =CLEAN(A5) -> setosa | D5: =TRIM(CLEAN(A5)) -> setosa | E5: =SUBSTITUTE(D5,"setosa","Setosa") -> Setosa | F5: =IF(ISBLANK(A5),"Missing","Complete") -> Complete | G5: =IF(COUNTIF($A$2:A5,A5)>1,"Duplicate","Unique") -> Duplicate
A6: =RAW_DATA!E6 -> setosa | B6: =TRIM(A6) -> setosa | C6: =CLEAN(A6) -> setosa | D6: =TRIM(CLEAN(A6)) -> setosa | E6: =SUBSTITUTE(D6,"setosa","Setosa") -> Setosa | F6: =IF(ISBLANK(A6),"Missing","Complete") -> Complete | G6: =IF(COUNTIF($A$2:A6,A6)>1,"Duplicate","Unique") -> Duplicate
A7: =RAW_DATA!E7 -> setosa | B7: =TRIM(A7) -> setosa | C7: =CLEAN(A7) -> setosa | D7: =TRIM(CLEAN(A7)) -> setosa | E7: =SUBSTITUTE(D7,"setosa","Setosa") -> Setosa | F7: =IF(ISBLANK(A7),"Missing","Complete") -> Complete | G7: =IF(COUNTIF($A$2:A7,A7)>1,"Duplicate","Unique") -> Duplicate
A8: =RAW_DATA!E8 -> setosa | B8: =TRIM(A8) -> setosa | C8: =CLEAN(A8) -> setosa | D8: =TRIM(CLEAN(A8)) -> setosa | E8: =SUBSTITUTE(D8,"setosa","Setosa") -> Setosa | F8: =IF(ISBLANK(A8),"Missing","Complete") -> Complete | G8: =IF(COUNTIF($A$2:A8,A8)>1,"Duplicate","Unique") -> Duplicate
A9: =RAW_DATA!E9 -> setosa | B9: =TRIM(A9) -> setosa | C9: =CLEAN(A9) -> setosa | D9: =TRIM(CLEAN(A9)) -> setosa | E9: =SUBSTITUTE(D9,"setosa","Setosa") -> Setosa | F9: =IF(ISBLANK(A9),"Missing","Complete") -> Complete | G9: =IF(COUNTIF($A$2:A9,A9)>1,"Duplicate","Unique") -> Duplicate
A10: =RAW_DATA!E10 -> setosa | B10: =TRIM(A10) -> setosa | C10: =CLEAN(A10) -> setosa | D10: =TRIM(CLEAN(A10)) -> setosa | E10: =SUBSTITUTE(D10,"setosa","Setosa") -> Setosa | F10: =IF(ISBLANK(A10),"Missing","Complete") -> Complete | G10: =IF(COUNTIF($A$2:A10,A10)>1,"Duplicate","Unique") -> Duplicate
A11: =RAW_DATA!E11 -> setosa | B11: =TRIM(A11) -> setosa | C11: =CLEAN(A11) -> setosa | D11: =TRIM(CLEAN(A11)) -> setosa | E11: =SUBSTITUTE(D11,"setosa","Setosa") -> Setosa | F11: =IF(ISBLANK(A11),"Missing","Complete") -> Complete | G11: =IF(COUNTIF($A$2:A11,A11)>1,"Duplicate","Unique") -> Duplicate
A12: =RAW_DATA!E12 -> setosa | B12: =TRIM(A12) -> setosa | C12: =CLEAN(A12) -> setosa | D12: =TRIM(CLEAN(A12)) -> setosa | E12: =SUBSTITUTE(D12,"setosa","Setosa") -> Setosa | F12: =IF(ISBLANK(A12),"Missing","Complete") -> Complete | G12: =IF(COUNTIF($A$2:A12,A12)>1,"Duplicate","Unique") -> Duplicate
A13: =RAW_DATA!E13 -> setosa | B13: =TRIM(A13) -> setosa | C13: =CLEAN(A13) -> setosa | D13: =TRIM(CLEAN(A13)) -> setosa | E13: =SUBSTITUTE(D13,"setosa","Setosa") -> Setosa | F13: =IF(ISBLANK(A13),"Missing","Complete") -> Complete | G13: =IF(COUNTIF($A$2:A13,A13)>1,"Duplicate","Unique") -> Duplicate
... A151: =RAW_DATA!E151 -> virginica | B151: =TRIM(A151) -> virginica | C151: =CLEAN(A151) -> virginica | D151: =TRIM(CLEAN(A151)) -> virginica | E151: =SUBSTITUTE(D151,"setosa","Setosa") -> virginica | F151: =IF(ISBLANK(A151),"Missing","Complete") -> Complete | G151: =IF(COUNTIF($A$2:A151,A151)>1,"Duplicate","Unique") -> Duplicate

Sheet STATISTICS
A1: DESCRIPTIVE STATISTICS
A3: Metric | B3: Sepal Length | C3: Sepal Width | D3: Petal Length | E3: Petal Width
A4: Mean | B4: =AVERAGE(RAW_DATA!A2:A151) -> 5.8433333 | C4: =AVERAGE(RAW_DATA!B2:B151) -> 3.054 | D4: =AVERAGE(RAW_DATA!C2:C151) -> 3.7586667 | E4: =AVERAGE(RAW_DATA!D2:D151) -> 1.1986667
A5: Median | B5: =MEDIAN(RAW_DATA!A2:A151) -> 5.8 | C5: =MEDIAN(RAW_DATA!B2:B151) -> 3 | D5: =MEDIAN(RAW_DATA!C2:C151) -> 4.35 | E5: =MEDIAN(RAW_DATA!D2:D151) -> 1.3
A6: Mode | B6: =_xlfn.MODE.SNGL(RAW_DATA!A2:A151) -> 5 | C6: =_xlfn.MODE.SNGL(RAW_DATA!B2:B151) -> 3 | D6: =_xlfn.MODE.SNGL(RAW_DATA!C2:C151) -> 1.5 | E6: =_xlfn.MODE.SNGL(RAW_DATA!D2:D151) -> 0.2
A7: Variance | B7: =_xlfn.VAR.S(RAW_DATA!A2:A151) -> 0.68569351 | C7: =_xlfn.VAR.S(RAW_DATA!B2:B151) -> 0.18800403 | D7: =_xlfn.VAR.S(RAW_DATA!C2:C151) -> 3.1131794 | E7: =_xlfn.VAR.S(RAW_DATA!D2:D151) -> 0.58241432
A8: Standard Deviation | B8: =_xlfn.STDEV.S(RAW_DATA!A2:A151) -> 0.82806613 | C8: =_xlfn.STDEV.S(RAW_DATA!B2:B151) -> 0.43359431 | D8: =_xlfn.STDEV.S(RAW_DATA!C2:C151) -> 1.7644204 | E8: =_xlfn.STDEV.S(RAW_DATA!D2:D151) -> 0.76316074
A9: Minimum | B9: =MIN(RAW_DATA!A2:A151) -> 4.3 | C9: =MIN(RAW_DATA!B2:B151) -> 2 | D9: =MIN(RAW_DATA!C2:C151) -> 1 | E9: =MIN(RAW_DATA!D2:D151) -> 0.1
A10: Maximum | B10: =MAX(RAW_DATA!A2:A151) -> 7.9 | C10: =MAX(RAW_DATA!B2:B151) -> 4.4 | D10: =MAX(RAW_DATA!C2:C151) -> 6.9 | E10: =MAX(RAW_DATA!D2:D151) -> 2.5
A13: SPECIES ANALYSIS
A14: Species | B14: Count | C14: Avg Sepal Length | D14: Avg Sepal Width | E14: Avg Petal Length | F14: Avg Petal Width
A15: {=_xlfn.UNIQUE(RAW_DATA!E2:E151)} -> setosa | B15: =COUNTIF(RAW_DATA!E:E,A15) -> 50 | C15: =AVERAGEIF(RAW_DATA!E:E,A15,RAW_DATA!A:A) -> 5.006 | D15: =AVERAGEIF(RAW_DATA!E:E,A15,RAW_DATA!B:B) -> 3.418 | E15: =AVERAGEIF(RAW_DATA!E:E,A15,RAW_DATA!C:C) -> 1.464 | F15: =AVERAGEIF(RAW_DATA!E:E,A15,RAW_DATA!D:D) -> 0.244
A16: versicolor | B16: =COUNTIF(RAW_DATA!E:E,A16) -> 50 | C16: =AVERAGEIF(RAW_DATA!E:E,A16,RAW_DATA!A:A) -> 5.936 | D16: =AVERAGEIF(RAW_DATA!E:E,A16,RAW_DATA!B:B) -> 2.77 | E16: =AVERAGEIF(RAW_DATA!E:E,A16,RAW_DATA!C:C) -> 4.26 | F16: =AVERAGEIF(RAW_DATA!E:E,A16,RAW_DATA!D:D) -> 1.326
A17: virginica | B17: =COUNTIF(RAW_DATA!E:E,A17) -> 50 | C17: =AVERAGEIF(RAW_DATA!E:E,A17,RAW_DATA!A:A) -> 6.588 | D17: =AVERAGEIF(RAW_DATA!E:E,A17,RAW_DATA!B:B) -> 2.974 | E17: =AVERAGEIF(RAW_DATA!E:E,A17,RAW_DATA!C:C) -> 5.552 | F17: =AVERAGEIF(RAW_DATA!E:E,A17,RAW_DATA!D:D) -> 2.026
A20: CORRELATION & COVARIANCE
A22: Relationship | B22: Correlation | C22: Covariance
A23: Sepal Length vs Petal Length | B23: =CORREL(RAW_DATA!A2:A151,RAW_DATA!C2:C151) -> 0.87175416 | C23: =_xlfn.COVARIANCE.S(RAW_DATA!A2:A151,RAW_DATA!C2:C151) -> 1.2736823
A24: Sepal Width vs Petal Width | B24: =CORREL(RAW_DATA!B2:B151,RAW_DATA!D2:D151) -> -0.35654409 | C24: =_xlfn.COVARIANCE.S(RAW_DATA!B2:B151,RAW_DATA!D2:D151) -> -0.11798121
A25: Petal Length vs Petal Width | B25: =CORREL(RAW_DATA!C2:C151,RAW_DATA!D2:D151) -> 0.9627571 | C25: =_xlfn.COVARIANCE.S(RAW_DATA!C2:C151,RAW_DATA!D2:D151) -> 1.2963875
A28: REGRESSION ANALYSIS
A30: Independent Variable | B30: Petal Length
A31: Dependent Variable | B31: Petal Width
A33: Slope | B33: =SLOPE(RAW_DATA!D2:D151,RAW_DATA!C2:C151) -> 0.41641913
A34: Intercept | B34: =INTERCEPT(RAW_DATA!D2:D151,RAW_DATA!C2:C151) -> -0.36651405
A35: R-Squared | B35: =RSQ(RAW_DATA!D2:D151,RAW_DATA!C2:C151) -> 0.92690123
A36: Predicted Width at Petal Length = 4 | B36: =_xlfn.FORECAST.LINEAR(4,RAW_DATA!D2:D151,RAW_DATA!C2:C151) -> 1.2991625

Sheet TESTS
A1: T-TEST | F1: CHI-SQUARE TEST
A3: Setosa Sepal Length | B3: Versicolor Sepal Length | D3: P-Value | F3: Species | G3: Small | H3: Medium | I3: Large | K3: SMALL | L3: MEDIUM | M3: LARGE
A4: {=_xlfn._xlws.FILTER(RAW_DATA!A2:A151,RAW_DATA!E2:E151="setosa")} -> 5.1 | B4: {=_xlfn._xlws.FILTER(RAW_DATA!A2:A151,RAW_DATA!E2:E151="versicolor")} -> 7 | D4: =_xlfn.T.TEST(_xlfn.ANCHORARRAY(A4),_xlfn.ANCHORARRAY(B4),2,2) -> 8.985235e-18 | F4: setosa | G4: =COUNTIFS(RAW_DATA!$E$2:$E$151,$F4,RAW_DATA!$C$2:$C$151,"<2") -> 50 | H4: =COUNTIFS(RAW_DATA!$E$2:$E$151,$F4,RAW_DATA!$C$2:$C$151,">=2",RAW_DATA!$C$2:$C$151,"<=5") -> 0 | I4: =COUNTIFS(RAW_DATA!$E$2:$E$151,$F4,RAW_DATA!$C$2:$C$151,">5") -> 0 | K4: =SUM($G4:$I4)*SUM(G$4:G$6)/SUM($G$4:$I$6) -> 16.666667 | L4: =SUM($G4:$I4)*SUM(H$4:H$6)/SUM($G$4:$I$6) -> 19.333333 | M4: =SUM($G4:$I4)*SUM(I$4:I$6)/SUM($G$4:$I$6) -> 14
A5: 4.9 | B5: 6.4 | F5: versicolor | G5: =COUNTIFS(RAW_DATA!$E$2:$E$151,$F5,RAW_DATA!$C$2:$C$151,"<2") -> 0 | H5: =COUNTIFS(RAW_DATA!$E$2:$E$151,$F5,RAW_DATA!$C$2:$C$151,">=2",RAW_DATA!$C$2:$C$151,"<=5") -> 49 | I5: =COUNTIFS(RAW_DATA!$E$2:$E$151,$F5,RAW_DATA!$C$2:$C$151,">5") -> 1 | K5: =SUM($G5:$I5)*SUM(G$4:G$6)/SUM($G$4:$I$6) -> 16.666667 | L5: =SUM($G5:$I5)*SUM(H$4:H$6)/SUM($G$4:$I$6) -> 19.333333 | M5: =SUM($G5:$I5)*SUM(I$4:I$6)/SUM($G$4:$I$6) -> 14
A6: 4.7 | B6: 6.9 | F6: virginica | G6: =COUNTIFS(RAW_DATA!$E$2:$E$151,$F6,RAW_DATA!$C$2:$C$151,"<2") -> 0 | H6: =COUNTIFS(RAW_DATA!$E$2:$E$151,$F6,RAW_DATA!$C$2:$C$151,">=2",RAW_DATA!$C$2:$C$151,"<=5") -> 9 | I6: =COUNTIFS(RAW_DATA!$E$2:$E$151,$F6,RAW_DATA!$C$2:$C$151,">5") -> 41 | K6: =SUM($G6:$I6)*SUM(G$4:G$6)/SUM($G$4:$I$6) -> 16.666667 | L6: =SUM($G6:$I6)*SUM(H$4:H$6)/SUM($G$4:$I$6) -> 19.333333 | M6: =SUM($G6:$I6)*SUM(I$4:I$6)/SUM($G$4:$I$6) -> 14
A7: 4.6 | B7: 5.5
A8: 5 | B8: 6.5 | K8: Chi-Square P-Value
A9: 5.4 | B9: 5.7 | K9: =_xlfn.CHISQ.TEST(G4:I6,K4:M6) -> 1.3549185e-52 | L9: =_xlfn.CHISQ.TEST(H4:J6,L4:N6) -> 4.2207689e-31 | M9: =_xlfn.CHISQ.TEST(I4:K6,M4:O6) -> 4.3085288e-16
A10: 4.6 | B10: 6.3 | F10: Setosa | G10: Versicolor | H10: Virginica
A11: 5 | B11: 4.9 | F11: {=_xlfn._xlws.FILTER(RAW_DATA!A2:A151,RAW_DATA!E2:E151="setosa")} -> 5.1 | G11: {=_xlfn._xlws.FILTER(RAW_DATA!A2:A151,RAW_DATA!E2:E151="versicolor")} -> 7 | H11: {=_xlfn._xlws.FILTER(RAW_DATA!A2:A151,RAW_DATA!E2:E151="virginica")} -> 6.3
A12: 4.4 | B12: 6.6 | F12: 4.9 | G12: 6.4 | H12: 5.8
A13: 4.9 | B13: 5.2 | F13: 4.7 | G13: 6.9 | H13: 7.1
A14: 5.4 | B14: 5 | F14: 4.6 | G14: 5.5 | H14: 6.3
A15: 4.8 | B15: 5.9 | F15: 5 | G15: 6.5 | H15: 6.5
A16: 4.8 | B16: 6 | F16: 5.4 | G16: 5.7 | H16: 7.6
A17: 4.3 | B17: 6.1 | F17: 4.6 | G17: 6.3 | H17: 4.9
A18: 5.8 | B18: 5.6 | F18: 5 | G18: 4.9 | H18: 7.3
A19: 5.7 | B19: 6.7 | F19: 4.4 | G19: 6.6 | H19: 6.7
A20: 5.4 | B20: 5.6 | F20: 4.9 | G20: 5.2 | H20: 7.2
A21: 5.1 | B21: 5.8 | F21: 5.4 | G21: 5 | H21: 6.5
A22: 5.7 | B22: 6.2 | F22: 4.8 | G22: 5.9 | H22: 6.4
A23: 5.1 | B23: 5.6 | F23: 4.8 | G23: 6 | H23: 6.8
... A53: 5 | B53: 5.7 | F53: 4.4 | G53: 5.8 | H53: 5.8
F54: 5 | G54: 5 | H54: 6.8
F55: 5.1 | G55: 5.6 | H55: 6.7
F56: 4.8 | G56: 5.7 | H56: 6.7
F57: 5.1 | G57: 5.7 | H57: 6.3
F58: 4.6 | G58: 6.2 | H58: 6.5
F59: 5.3 | G59: 5.1 | H59: 6.2
F60: 5 | G60: 5.7 | H60: 5.9

Sheet PIVOT
A1: Row Labels | B1: Row Labels | C1: Sum of Avg Sepal Length | E1: Row Labels | F1: Sum of Avg Sepal Width | H1: Row Labels | I1: Sum of Avg Petal Length
A2: setosa | B2: setosa | C2: 5.006 | E2: setosa | F2: 3.418 | H2: setosa | I2: 1.464
A3: versicolor | B3: versicolor | C3: 5.936 | E3: versicolor | F3: 2.77 | H3: versicolor | I3: 4.26
A4: virginica | B4: virginica | C4: 6.588 | E4: virginica | F4: 2.974 | H4: virginica | I4: 5.552
A5: Grand Total | B5: Grand Total | C5: 17.53 | E5: Grand Total | F5: 9.162 | H5: Grand Total | I5: 11.276
A19: Row Labels | B19: Sum of Avg Petal Width
A20: setosa | B20: 0.244
A21: versicolor | B21: 1.326
A22: virginica | B22: 2.026
A23: Grand Total | B23: 3.596

Sheet DASH BOARD

Sheet POWER_PIVOT

Sheet Sheet10

Sheet Sheet11
