Workbook
Name Slicer_Country: #N/A
Name Slicer_Platform: #N/A
Name Slicer_Platform1: #N/A

Sheet sentiment
B1: Unnamed: 0 | C1: Text | D1: Sentiment | E1: Timestamp | F1: User | G1: Platform | H1: Hashtags | I1: Retweets | J1: Likes | K1: Country | L1: Year | M1: Month | N1: Day | O1: Hour
A2: 0 | B2: 0 | C2: Enjoying a beautiful day at the park! | D2: Positive | E2: 44941.521 | F2: User123 | G2: Twitter | H2: #Nature #Park | I2: 15 | J2: 30 | K2: USA | L2: 2023 | M2: 1 | N2: 15 | O2: 12
A3: 1 | B3: 1 | C3: Traffic was terrible this morning. | D3: Negative | E3: 44941.365 | F3: CommuterX | G3: Twitter | H3: #Traffic #Morning | I3: 5 | J3: 10 | K3: Canada | L3: 2023 | M3: 1 | N3: 15 | O3: 8
A4: 2 | B4: 2 | C4: Just finished an amazing workout! ðŸ’ª | D4: Positive | E4: 44941.656 | F4: FitnessFan | G4: Instagram | H4: #Fitness #Workout | I4: 20 | J4: 40 | K4: USA | L4: 2023 | M4: 1 | N4: 15 | O4: 15
A5: 3 | B5: 3 | C5: Excited about the upcoming weekend getaway! | D5: Positive | E5: 44941.764 | F5: AdventureX | G5: Facebook | H5: #Travel #Adventure | I5: 8 | J5: 15 | K5: UK | L5: 2023 | M5: 1 | N5: 15 | O5: 18
A6: 4 | B6: 4 | C6: Trying out a new recipe for dinner tonight. | D6: Neutral | E6: 44941.83 | F6: ChefCook | G6: Instagram | H6: #Cooking #Food | I6: 12 | J6: 25 | K6: Australia | L6: 2023 | M6: 1 | N6: 15 | O6: 19
A7: 5 | B7: 5 | C7: Feeling grateful for the little things in life. | D7: Positive | E7: 44942.382 | F7: GratitudeNow | G7: Twitter | H7: #Gratitude #PositiveVibes | I7: 25 | J7: 50 | K7: India | L7: 2023 | M7: 1 | N7: 16 | O7: 9
A8: 6 | B8: 6 | C8: Rainy days call for cozy blankets and hot cocoa. | D8: Positive | E8: 44942.615 | F8: RainyDays | G8: Facebook | H8: #RainyDays #Cozy | I8: 10 | J8: 20 | K8: Canada | L8: 2023 | M8: 1 | N8: 16 | O8: 14
A9: 7 | B9: 7 | C9: The new movie release is a must-watch! | D9: Positive | E9: 44942.812 | F9: MovieBuff | G9: Instagram | H9: #MovieNight #MustWatch | I9: 15 | J9: 30 | K9: USA | L9: 2023 | M9: 1 | N9: 16 | O9: 19
A10: 8 | B10: 8 | C10: Political discussions heating up on the timeline. | D10: Negative | E10: 44943.333 | F10: DebateTalk | G10: Twitter | H10: #Politics #Debate | I10: 30 | J10: 60 | K10: USA | L10: 2023 | M10: 1 | N10: 17 | O10: 8
A11: 9 | B11: 9 | C11: Missing summer vibes and beach days. | D11: Neutral | E11: 44943.514 | F11: BeachLover | G11: Facebook | H11: #Summer #BeachDays | I11: 18 | J11: 35 | K11: Australia | L11: 2023 | M11: 1 | N11: 17 | O11: 12
A12: 10 | B12: 10 | C12: Just published a new blog post. Check it out! | D12: Positive | E12: 44943.635 | F12: BloggerX | G12: Instagram | H12: #Blogging #NewPost | I12: 22 | J12: 45 | K12: USA | L12: 2023 | M12: 1 | N12: 17 | O12: 15
A13: 11 | B13: 11 | C13: Feeling a bit under the weather today. | D13: Negative | E13: 44944.438 | F13: WellnessCheck | G13: Twitter | H13: #SickDay #Health | I13: 7 | J13: 15 | K13: Canada | L13: 2023 | M13: 1 | N13: 18 | O13: 10
... A733: 732 | B733: 736 | C733: Organizing a virtual talent show during challenging times, bringing smiles to classmates' faces! | D733: Happy | E733: 44150.635 | F733: VirtualTalentShowSuccessHighSchool | G733: Instagram | H733: #VirtualEntertainment #HighSchoolPositivity | I733: 24 | J733: 47 | K733: USA | L733: 2020 | M733: 11 | N733: 15 | O733: 15

Sheet Raw_Data
B1: Unnamed: 0 | C1: Text | D1: Sentiment | E1: Timestamp | F1: User | G1: Platform | H1: Hashtags | I1: Retweets | J1: Likes | K1: Country | L1: Year | M1: Month | N1: Day | O1: Hour
A2: 0 | B2: 0 | C2: Enjoying a beautiful day at the park! | D2: Positive | E2: 44941.521 | F2: User123 | G2: Twitter | H2: #Nature #Park | I2: 15 | J2: 30 | K2: USA | L2: 2023 | M2: 1 | N2: 15 | O2: 12
A3: 1 | B3: 1 | C3: Traffic was terrible this morning. | D3: Negative | E3: 44941.365 | F3: CommuterX | G3: Twitter | H3: #Traffic #Morning | I3: 5 | J3: 10 | K3: Canada | L3: 2023 | M3: 1 | N3: 15 | O3: 8
A4: 2 | B4: 2 | C4: Just finished an amazing workout! ðŸ’ª | D4: Positive | E4: 44941.656 | F4: FitnessFan | G4: Instagram | H4: #Fitness #Workout | I4: 20 | J4: 40 | K4: USA | L4: 2023 | M4: 1 | N4: 15 | O4: 15
A5: 3 | B5: 3 | C5: Excited about the upcoming weekend getaway! | D5: Positive | E5: 44941.764 | F5: AdventureX | G5: Facebook | H5: #Travel #Adventure | I5: 8 | J5: 15 | K5: UK | L5: 2023 | M5: 1 | N5: 15 | O5: 18
A6: 4 | B6: 4 | C6: Trying out a new recipe for dinner tonight. | D6: Neutral | E6: 44941.83 | F6: ChefCook | G6: Instagram | H6: #Cooking #Food | I6: 12 | J6: 25 | K6: Australia | L6: 2023 | M6: 1 | N6: 15 | O6: 19
A7: 5 | B7: 5 | C7: Feeling grateful for the little things in life. | D7: Positive | E7: 44942.382 | F7: GratitudeNow | G7: Twitter | H7: #Gratitude #PositiveVibes | I7: 25 | J7: 50 | K7: India | L7: 2023 | M7: 1 | N7: 16 | O7: 9
A8: 6 | B8: 6 | C8: Rainy days call for cozy blankets and hot cocoa. | D8: Positive | E8: 44942.615 | F8: RainyDays | G8: Facebook | H8: #RainyDays #Cozy | I8: 10 | J8: 20 | K8: Canada | L8: 2023 | M8: 1 | N8: 16 | O8: 14
A9: 7 | B9: 7 | C9: The new movie release is a must-watch! | D9: Positive | E9: 44942.812 | F9: MovieBuff | G9: Instagram | H9: #MovieNight #MustWatch | I9: 15 | J9: 30 | K9: USA | L9: 2023 | M9: 1 | N9: 16 | O9: 19
A10: 8 | B10: 8 | C10: Political discussions heating up on the timeline. | D10: Negative | E10: 44943.333 | F10: DebateTalk | G10: Twitter | H10: #Politics #Debate | I10: 30 | J10: 60 | K10: USA | L10: 2023 | M10: 1 | N10: 17 | O10: 8
A11: 9 | B11: 9 | C11: Missing summer vibes and beach days. | D11: Neutral | E11: 44943.514 | F11: BeachLover | G11: Facebook | H11: #Summer #BeachDays | I11: 18 | J11: 35 | K11: Australia | L11: 2023 | M11: 1 | N11: 17 | O11: 12
A12: 10 | B12: 10 | C12: Just published a new blog post. Check it out! | D12: Positive | E12: 44943.635 | F12: BloggerX | G12: Instagram | H12: #Blogging #NewPost | I12: 22 | J12: 45 | K12: USA | L12: 2023 | M12: 1 | N12: 17 | O12: 15
A13: 11 | B13: 11 | C13: Feeling a bit under the weather today. | D13: Negative | E13: 44944.438 | F13: WellnessCheck | G13: Twitter | H13: #SickDay #Health | I13: 7 | J13: 15 | K13: Canada | L13: 2023 | M13: 1 | N13: 18 | O13: 10
... A733: 732 | B733: 736 | C733: Organizing a virtual talent show during challenging times, bringing smiles to classmates' faces! | D733: Happy | E733: 44150.635 | F733: VirtualTalentShowSuccessHighSchool | G733: Instagram | H733: #VirtualEntertainment #HighSchoolPositivity | I733: 24 | J733: 47 | K733: USA | L733: 2020 | M733: 11 | N733: 15 | O733: 15

Sheet Clean_Data
B1: Unnamed: 0 | C1: Text | D1: Sentiment | E1: Timestamp | F1: User | G1: Platform | H1: Hashtags | I1: Retweets | J1: Likes | K1: Country | L1: Year | M1: Month | N1: Day | O1: Hour | P1: clean_text | Q1: clean_sentiment | R1: clean user | S1: clean_platform | T1: clen_hashtags | U1: clean_country | V1: clean_timestamp | W1: Duplicate_flag | X1: Engagement | Y1: engagement rate | Z1: Date | AA1: Month
A2: =Raw_Data!A2 -> 0 | B2: =Raw_Data!B2 -> 0 | C2: =Raw_Data!C2 -> Enjoying a beautiful day at the park! | D2: =Raw_Data!D2 -> Positive | E2: =Raw_Data!E2 -> 44941.521 | F2: =Raw_Data!F2 -> User123 | G2: =Raw_Data!G2 -> Twitter | H2: =Raw_Data!H2 -> #Nature #Park | ... O2: =Raw_Data!O2 -> 12 | P2: =TRIM(CLEAN(C2)) -> Enjoying a beautiful day at the park! | Q2: =PROPER(TRIM(CLEAN(D2))) -> Positive | R2: =TRIM(CLEAN(F2)) -> User123 | S2: =TRIM(CLEAN(G2)) -> Twitter | T2: =SUBSTITUTE(TRIM(CLEAN(H2))," ",",") -> #Nature,#Park | U2: =TRIM(CLEAN(K2)) -> USA | V2: =IFERROR(VALUE(E2),E2) -> 44941.521 | W2: =COUNTIFS($F$2:F2,F2,$E$2:E2,E2)>1 -> FALSE | X2: =I2+J2 -> 45 | Y2: =IFERROR(J2/(I2+J2),0) -> 0.66666667 | Z2: =TEXT(DATE(L2, M2, N2), "mmm d, yyyy") -> Jan 15, 2023 | AA2: =LEFT(Z2,3) -> Jan
A3: =Raw_Data!A3 -> 1 | B3: =Raw_Data!B3 -> 1 | C3: =Raw_Data!C3 -> Traffic was terrible this morning. | D3: =Raw_Data!D3 -> Negative | E3: =Raw_Data!E3 -> 44941.365 | F3: =Raw_Data!F3 -> CommuterX | G3: =Raw_Data!G3 -> Twitter | H3: =Raw_Data!H3 -> #Traffic #Morning | ... O3: =Raw_Data!O3 -> 8 | P3: =TRIM(CLEAN(C3)) -> Traffic was terrible this morning. | Q3: =PROPER(TRIM(CLEAN(D3))) -> Negative | R3: =TRIM(CLEAN(F3)) -> CommuterX | S3: =TRIM(CLEAN(G3)) -> Twitter | T3: =SUBSTITUTE(TRIM(CLEAN(H3))," ",",") -> #Traffic,#Morning | U3: =TRIM(CLEAN(K3)) -> Canada | V3: =IFERROR(VALUE(E3),E3) -> 44941.365 | W3: =COUNTIFS($F$2:F3,F3,$E$2:E3,E3)>1 -> FALSE | X3: =I3+J3 -> 15 | Y3: =IFERROR(J3/(I3+J3),0) -> 0.66666667 | Z3: =TEXT(DATE(L3, M3, N3), "mmm d, yyyy") -> Jan 15, 2023 | AA3: =LEFT(Z3,3) -> Jan | AE3: Likes | AF3: Retweets
A4: =Raw_Data!A4 -> 2 | B4: =Raw_Data!B4 -> 2 | C4: =Raw_Data!C4 -> Just finished an amazing workout! ðŸ’ª | D4: =Raw_Data!D4 -> Positive | E4: =Raw_Data!E4 -> 44941.656 | F4: =Raw_Data!F4 -> FitnessFan | G4: =Raw_Data!G4 -> Instagram | H4: =Raw_Data!H4 -> #Fitness #Workout | ... O4: =Raw_Data!O4 -> 15 | P4: =TRIM(CLEAN(C4)) -> Just finished an amazing workout! ðŸ’ª | Q4: =PROPER(TRIM(CLEAN(D4))) -> Positive | R4: =TRIM(CLEAN(F4)) -> FitnessFan | S4: =TRIM(CLEAN(G4)) -> Instagram | T4: =SUBSTITUTE(TRIM(CLEAN(H4))," ",",") -> #Fitness,#Workout | U4: =TRIM(CLEAN(K4)) -> USA | V4: =IFERROR(VALUE(E4),E4) -> 44941.656 | W4: =COUNTIFS($F$2:F4,F4,$E$2:E4,E4)>1 -> FALSE | X4: =I4+J4 -> 60 | Y4: =IFERROR(J4/(I4+J4),0) -> 0.66666667 | Z4: =TEXT(DATE(L4, M4, N4), "mmm d, yyyy") -> Jan 15, 2023 | AA4: =LEFT(Z4,3) -> Jan | AC4: Total Twiter | AE4: =SUMIF(S:S,"Twitter",J:J) -> 10099 | AF4: =SUMIF(S:S,"Twitter",I:I) -> 5069
A5: =Raw_Data!A5 -> 3 | B5: =Raw_Data!B5 -> 3 | C5: =Raw_Data!C5 -> Excited about the upcoming weekend getaway! | D5: =Raw_Data!D5 -> Positive | E5: =Raw_Data!E5 -> 44941.764 | F5: =Raw_Data!F5 -> AdventureX | G5: =Raw_Data!G5 -> Facebook | H5: =Raw_Data!H5 -> #Travel #Adventure | ... O5: =Raw_Data!O5 -> 18 | P5: =TRIM(CLEAN(C5)) -> Excited about the upcoming weekend getaway! | Q5: =PROPER(TRIM(CLEAN(D5))) -> Positive | R5: =TRIM(CLEAN(F5)) -> AdventureX | S5: =TRIM(CLEAN(G5)) -> Facebook | T5: =SUBSTITUTE(TRIM(CLEAN(H5))," ",",") -> #Travel,#Adventure | U5: =TRIM(CLEAN(K5)) -> UK | V5: =IFERROR(VALUE(E5),E5) -> 44941.764 | W5: =COUNTIFS($F$2:F5,F5,$E$2:E5,E5)>1 -> FALSE | X5: =I5+J5 -> 23 | Y5: =IFERROR(J5/(I5+J5),0) -> 0.65217391 | Z5: =TEXT(DATE(L5, M5, N5), "mmm d, yyyy") -> Jan 15, 2023 | AA5: =LEFT(Z5,3) -> Jan | AC5: Total Facebook | AE5: =SUMIF(S:S,"Facebook",J:J) -> 9672 | AF5: =SUMIF(S:S,"Facebook",I:I) -> 4844
A6: =Raw_Data!A6 -> 4 | B6: =Raw_Data!B6 -> 4 | C6: =Raw_Data!C6 -> Trying out a new recipe for dinner tonight. | D6: =Raw_Data!D6 -> Neutral | E6: =Raw_Data!E6 -> 44941.83 | F6: =Raw_Data!F6 -> ChefCook | G6: =Raw_Data!G6 -> Instagram | H6: =Raw_Data!H6 -> #Cooking #Food | ... O6: =Raw_Data!O6 -> 19 | P6: =TRIM(CLEAN(C6)) -> Trying out a new recipe for dinner tonight. | Q6: =PROPER(TRIM(CLEAN(D6))) -> Neutral | R6: =TRIM(CLEAN(F6)) -> ChefCook | S6: =TRIM(CLEAN(G6)) -> Instagram | T6: =SUBSTITUTE(TRIM(CLEAN(H6))," ",",") -> #Cooking,#Food | U6: =TRIM(CLEAN(K6)) -> Australia | V6: =IFERROR(VALUE(E6),E6) -> 44941.83 | W6: =COUNTIFS($F$2:F6,F6,$E$2:E6,E6)>1 -> FALSE | X6: =I6+J6 -> 37 | Y6: =IFERROR(J6/(I6+J6),0) -> 0.67567568 | Z6: =TEXT(DATE(L6, M6, N6), "mmm d, yyyy") -> Jan 15, 2023 | AA6: =LEFT(Z6,3) -> Jan | AC6: Total Instagram | AE6: =SUMIF(S:S,"Instagram",J:J) -> 11633 | AF6: =SUMIF(S:S,"Instagram",I:I) -> 5831
A7: =Raw_Data!A7 -> 5 | B7: =Raw_Data!B7 -> 5 | C7: =Raw_Data!C7 -> Feeling grateful for the little things in life. | D7: =Raw_Data!D7 -> Positive | E7: =Raw_Data!E7 -> 44942.382 | F7: =Raw_Data!F7 -> GratitudeNow | G7: =Raw_Data!G7 -> Twitter | H7: =Raw_Data!H7 -> #Gratitude #PositiveVibes | ... O7: =Raw_Data!O7 -> 9 | P7: =TRIM(CLEAN(C7)) -> Feeling grateful for the little things in life. | Q7: =PROPER(TRIM(CLEAN(D7))) -> Positive | R7: =TRIM(CLEAN(F7)) -> GratitudeNow | S7: =TRIM(CLEAN(G7)) -> Twitter | T7: =SUBSTITUTE(TRIM(CLEAN(H7))," ",",") -> #Gratitude,#PositiveVibes | U7: =TRIM(CLEAN(K7)) -> India | V7: =IFERROR(VALUE(E7),E7) -> 44942.382 | W7: =COUNTIFS($F$2:F7,F7,$E$2:E7,E7)>1 -> FALSE | X7: =I7+J7 -> 75 | Y7: =IFERROR(J7/(I7+J7),0) -> 0.66666667 | Z7: =TEXT(DATE(L7, M7, N7), "mmm d, yyyy") -> Jan 16, 2023 | AA7: =LEFT(Z7,3) -> Jan
A8: =Raw_Data!A8 -> 6 | B8: =Raw_Data!B8 -> 6 | C8: =Raw_Data!C8 -> Rainy days call for cozy blankets and hot cocoa. | D8: =Raw_Data!D8 -> Positive | E8: =Raw_Data!E8 -> 44942.615 | F8: =Raw_Data!F8 -> RainyDays | G8: =Raw_Data!G8 -> Facebook | H8: =Raw_Data!H8 -> #RainyDays #Cozy | ... O8: =Raw_Data!O8 -> 14 | P8: =TRIM(CLEAN(C8)) -> Rainy days call for cozy blankets and hot cocoa. | Q8: =PROPER(TRIM(CLEAN(D8))) -> Positive | R8: =TRIM(CLEAN(F8)) -> RainyDays | S8: =TRIM(CLEAN(G8)) -> Facebook | T8: =SUBSTITUTE(TRIM(CLEAN(H8))," ",",") -> #RainyDays,#Cozy | U8: =TRIM(CLEAN(K8)) -> Canada | V8: =IFERROR(VALUE(E8),E8) -> 44942.615 | W8: =COUNTIFS($F$2:F8,F8,$E$2:E8,E8)>1 -> FALSE | X8: =I8+J8 -> 30 | Y8: =IFERROR(J8/(I8+J8),0) -> 0.66666667 | Z8: =TEXT(DATE(L8, M8, N8), "mmm d, yyyy") -> Jan 16, 2023 | AA8: =LEFT(Z8,3) -> Jan
A9: =Raw_Data!A9 -> 7 | B9: =Raw_Data!B9 -> 7 | C9: =Raw_Data!C9 -> The new movie release is a must-watch! | D9: =Raw_Data!D9 -> Positive | E9: =Raw_Data!E9 -> 44942.812 | F9: =Raw_Data!F9 -> MovieBuff | G9: =Raw_Data!G9 -> Instagram | H9: =Raw_Data!H9 -> #MovieNight #MustWatch | ... O9: =Raw_Data!O9 -> 19 | P9: =TRIM(CLEAN(C9)) -> The new movie release is a must-watch! | Q9: =PROPER(TRIM(CLEAN(D9))) -> Positive | R9: =TRIM(CLEAN(F9)) -> MovieBuff | S9: =TRIM(CLEAN(G9)) -> Instagram | T9: =SUBSTITUTE(TRIM(CLEAN(H9))," ",",") -> #MovieNight,#MustWatch | U9: =TRIM(CLEAN(K9)) -> USA | V9: =IFERROR(VALUE(E9),E9) -> 44942.812 | W9: =COUNTIFS($F$2:F9,F9,$E$2:E9,E9)>1 -> FALSE | X9: =I9+J9 -> 45 | Y9: =IFERROR(J9/(I9+J9),0) -> 0.66666667 | Z9: =TEXT(DATE(L9, M9, N9), "mmm d, yyyy") -> Jan 16, 2023 | AA9: =LEFT(Z9,3) -> Jan
A10: =Raw_Data!A10 -> 8 | B10: =Raw_Data!B10 -> 8 | C10: =Raw_Data!C10 -> Political discussions heating up on the timeline. | D10: =Raw_Data!D10 -> Negative | E10: =Raw_Data!E10 -> 44943.333 | F10: =Raw_Data!F10 -> DebateTalk | G10: =Raw_Data!G10 -> Twitter | H10: =Raw_Data!H10 -> #Politics #Debate | ... O10: =Raw_Data!O10 -> 8 | P10: =TRIM(CLEAN(C10)) -> Political discussions heating up on the timeline. | Q10: =PROPER(TRIM(CLEAN(D10))) -> Negative | R10: =TRIM(CLEAN(F10)) -> DebateTalk | S10: =TRIM(CLEAN(G10)) -> Twitter | T10: =SUBSTITUTE(TRIM(CLEAN(H10))," ",",") -> #Politics,#Debate | U10: =TRIM(CLEAN(K10)) -> USA | V10: =IFERROR(VALUE(E10),E10) -> 44943.333 | W10: =COUNTIFS($F$2:F10,F10,$E$2:E10,E10)>1 -> FALSE | X10: =I10+J10 -> 90 | Y10: =IFERROR(J10/(I10+J10),0) -> 0.66666667 | Z10: =TEXT(DATE(L10, M10, N10), "mmm d, yyyy") -> Jan 17, 2023 | AA10: =LEFT(Z10,3) -> Jan
A11: =Raw_Data!A11 -> 9 | B11: =Raw_Data!B11 -> 9 | C11: =Raw_Data!C11 -> Missing summer vibes and beach days. | D11: =Raw_Data!D11 -> Neutral | E11: =Raw_Data!E11 -> 44943.514 | F11: =Raw_Data!F11 -> BeachLover | G11: =Raw_Data!G11 -> Facebook | H11: =Raw_Data!H11 -> #Summer #BeachDays | ... O11: =Raw_Data!O11 -> 12 | P11: =TRIM(CLEAN(C11)) -> Missing summer vibes and beach days. | Q11: =PROPER(TRIM(CLEAN(D11))) -> Neutral | R11: =TRIM(CLEAN(F11)) -> BeachLover | S11: =TRIM(CLEAN(G11)) -> Facebook | T11: =SUBSTITUTE(TRIM(CLEAN(H11))," ",",") -> #Summer,#BeachDays | U11: =TRIM(CLEAN(K11)) -> Australia | V11: =IFERROR(VALUE(E11),E11) -> 44943.514 | W11: =COUNTIFS($F$2:F11,F11,$E$2:E11,E11)>1 -> FALSE | X11: =I11+J11 -> 53 | Y11: =IFERROR(J11/(I11+J11),0) -> 0.66037736 | Z11: =TEXT(DATE(L11, M11, N11), "mmm d, yyyy") -> Jan 17, 2023 | AA11: =LEFT(Z11,3) -> Jan
A12: =Raw_Data!A12 -> 10 | B12: =Raw_Data!B12 -> 10 | C12: =Raw_Data!C12 -> Just published a new blog post. Check it out! | D12: =Raw_Data!D12 -> Positive | E12: =Raw_Data!E12 -> 44943.635 | F12: =Raw_Data!F12 -> BloggerX | G12: =Raw_Data!G12 -> Instagram | H12: =Raw_Data!H12 -> #Blogging #NewPost | ... O12: =Raw_Data!O12 -> 15 | P12: =TRIM(CLEAN(C12)) -> Just published a new blog post. Check it out! | Q12: =PROPER(TRIM(CLEAN(D12))) -> Positive | R12: =TRIM(CLEAN(F12)) -> BloggerX | S12: =TRIM(CLEAN(G12)) -> Instagram | T12: =SUBSTITUTE(TRIM(CLEAN(H12))," ",",") -> #Blogging,#NewPost | U12: =TRIM(CLEAN(K12)) -> USA | V12: =IFERROR(VALUE(E12),E12) -> 44943.635 | W12: =COUNTIFS($F$2:F12,F12,$E$2:E12,E12)>1 -> FALSE | X12: =I12+J12 -> 67 | Y12: =IFERROR(J12/(I12+J12),0) -> 0.67164179 | Z12: =TEXT(DATE(L12, M12, N12), "mmm d, yyyy") -> Jan 17, 2023 | AA12: =LEFT(Z12,3) -> Jan
A13: =Raw_Data!A13 -> 11 | B13: =Raw_Data!B13 -> 11 | C13: =Raw_Data!C13 -> Feeling a bit under the weather today. | D13: =Raw_Data!D13 -> Negative | E13: =Raw_Data!E13 -> 44944.438 | F13: =Raw_Data!F13 -> WellnessCheck | G13: =Raw_Data!G13 -> Twitter | H13: =Raw_Data!H13 -> #SickDay #Health | ... O13: =Raw_Data!O13 -> 10 | P13: =TRIM(CLEAN(C13)) -> Feeling a bit under the weather today. | Q13: =PROPER(TRIM(CLEAN(D13))) -> Negative | R13: =TRIM(CLEAN(F13)) -> WellnessCheck | S13: =TRIM(CLEAN(G13)) -> Twitter | T13: =SUBSTITUTE(TRIM(CLEAN(H13))," ",",") -> #SickDay,#Health | U13: =TRIM(CLEAN(K13)) -> Canada | V13: =IFERROR(VALUE(E13),E13) -> 44944.438 | W13: =COUNTIFS($F$2:F13,F13,$E$2:E13,E13)>1 -> FALSE | X13: =I13+J13 -> 22 | Y13: =IFERROR(J13/(I13+J13),0) -> 0.68181818 | Z13: =TEXT(DATE(L13, M13, N13), "mmm d, yyyy") -> Jan 18, 2023 | AA13: =LEFT(Z13,3) -> Jan
A14: =Raw_Data!A14 -> 12 | B14: =Raw_Data!B14 -> 12 | C14: =Raw_Data!C14 -> Exploring the city's hidden gems. | D14: =Raw_Data!D14 -> Positive | E14: =Raw_Data!E14 -> 44944.618 | F14: =Raw_Data!F14 -> UrbanExplorer | G14: =Raw_Data!G14 -> Facebook | H14: =Raw_Data!H14 -> #CityExplore #HiddenGems | ... O14: =Raw_Data!O14 -> 14 | P14: =TRIM(CLEAN(C14)) -> Exploring the city's hidden gems. | Q14: =PROPER(TRIM(CLEAN(D14))) -> Positive | R14: =TRIM(CLEAN(F14)) -> UrbanExplorer | S14: =TRIM(CLEAN(G14)) -> Facebook | T14: =SUBSTITUTE(TRIM(CLEAN(H14))," ",",") -> #CityExplore,#HiddenGems | U14: =TRIM(CLEAN(K14)) -> UK | V14: =IFERROR(VALUE(E14),E14) -> 44944.618 | W14: =COUNTIFS($F$2:F14,F14,$E$2:E14,E14)>1 -> FALSE | X14: =I14+J14 -> 37 | Y14: =IFERROR(J14/(I14+J14),0) -> 0.67567568 | Z14: =TEXT(DATE(L14, M14, N14), "mmm d, yyyy") -> Jan 18, 2023 | AA14: =LEFT(Z14,3) -> Jan
A15: =Raw_Data!A15 -> 13 | B15: =Raw_Data!B15 -> 13 | C15: =Raw_Data!C15 -> New year, new fitness goals! ðŸ’ª | D15: =Raw_Data!D15 -> Positive | E15: =Raw_Data!E15 -> 44944.75 | F15: =Raw_Data!F15 -> FitJourney | G15: =Raw_Data!G15 -> Instagram | H15: =Raw_Data!H15 -> #NewYear #FitnessGoals | ... O15: =Raw_Data!O15 -> 18 | P15: =TRIM(CLEAN(C15)) -> New year, new fitness goals! ðŸ’ª | Q15: =PROPER(TRIM(CLEAN(D15))) -> Positive | R15: =TRIM(CLEAN(F15)) -> FitJourney | S15: =TRIM(CLEAN(G15)) -> Instagram | T15: =SUBSTITUTE(TRIM(CLEAN(H15))," ",",") -> #NewYear,#FitnessGoals | U15: =TRIM(CLEAN(K15)) -> USA | V15: =IFERROR(VALUE(E15),E15) -> 44944.75 | W15: =COUNTIFS($F$2:F15,F15,$E$2:E15,E15)>1 -> FALSE | X15: =I15+J15 -> 83 | Y15: =IFERROR(J15/(I15+J15),0) -> 0.6626506 | Z15: =TEXT(DATE(L15, M15, N15), "mmm d, yyyy") -> Jan 18, 2023 | AA15: =LEFT(Z15,3) -> Jan
A16: =Raw_Data!A16 -> 14 | B16: =Raw_Data!B16 -> 14 | C16: =Raw_Data!C16 -> Technology is changing the way we live. | D16: =Raw_Data!D16 -> Neutral | E16: =Raw_Data!E16 -> 44945.406 | F16: =Raw_Data!F16 -> TechEnthusiast | G16: =Raw_Data!G16 -> Twitter | H16: =Raw_Data!H16 -> #Tech #Innovation | ... O16: =Raw_Data!O16 -> 9 | P16: =TRIM(CLEAN(C16)) -> Technology is changing the way we live. | Q16: =PROPER(TRIM(CLEAN(D16))) -> Neutral | R16: =TRIM(CLEAN(F16)) -> TechEnthusiast | S16: =TRIM(CLEAN(G16)) -> Twitter | T16: =SUBSTITUTE(TRIM(CLEAN(H16))," ",",") -> #Tech,#Innovation | U16: =TRIM(CLEAN(K16)) -> India | V16: =IFERROR(VALUE(E16),E16) -> 44945.406 | W16: =COUNTIFS($F$2:F16,F16,$E$2:E16,E16)>1 -> FALSE | X16: =I16+J16 -> 45 | Y16: =IFERROR(J16/(I16+J16),0) -> 0.66666667 | Z16: =TEXT(DATE(L16, M16, N16), "mmm d, yyyy") -> Jan 19, 2023 | AA16: =LEFT(Z16,3) -> Jan
A17: =Raw_Data!A17 -> 15 | B17: =Raw_Data!B17 -> 15 | C17: =Raw_Data!C17 -> Reflecting on the past and looking ahead. | D17: =Raw_Data!D17 -> Positive | E17: =Raw_Data!E17 -> 44945.556 | F17: =Raw_Data!F17 -> Reflections | G17: =Raw_Data!G17 -> Facebook | H17: =Raw_Data!H17 -> #Reflection #Future | ... O17: =Raw_Data!O17 -> 13 | P17: =TRIM(CLEAN(C17)) -> Reflecting on the past and looking ahead. | Q17: =PROPER(TRIM(CLEAN(D17))) -> Positive | R17: =TRIM(CLEAN(F17)) -> Reflections | S17: =TRIM(CLEAN(G17)) -> Facebook | T17: =SUBSTITUTE(TRIM(CLEAN(H17))," ",",") -> #Reflection,#Future | U17: =TRIM(CLEAN(K17)) -> USA | V17: =IFERROR(VALUE(E17),E17) -> 44945.556 | W17: =COUNTIFS($F$2:F17,F17,$E$2:E17,E17)>1 -> FALSE | X17: =I17+J17 -> 60 | Y17: =IFERROR(J17/(I17+J17),0) -> 0.66666667 | Z17: =TEXT(DATE(L17, M17, N17), "mmm d, yyyy") -> Jan 19, 2023 | AA17: =LEFT(Z17,3) -> Jan
A18: =Raw_Data!A18 -> 16 | B18: =Raw_Data!B18 -> 16 | C18: =Raw_Data!C18 -> Just adopted a cute furry friend! ðŸ¾ | D18: =Raw_Data!D18 -> Positive | E18: =Raw_Data!E18 -> 44945.715 | F18: =Raw_Data!F18 -> PetAdopter | G18: =Raw_Data!G18 -> Instagram | H18: =Raw_Data!H18 -> #PetAdoption #FurryFriend | ... O18: =Raw_Data!O18 -> 17 | P18: =TRIM(CLEAN(C18)) -> Just adopted a cute furry friend! ðŸ¾ | Q18: =PROPER(TRIM(CLEAN(D18))) -> Positive | R18: =TRIM(CLEAN(F18)) -> PetAdopter | S18: =TRIM(CLEAN(G18)) -> Instagram | T18: =SUBSTITUTE(TRIM(CLEAN(H18))," ",",") -> #PetAdoption,#FurryFriend | U18: =TRIM(CLEAN(K18)) -> Canada | V18: =IFERROR(VALUE(E18),E18) -> 44945.715 | W18: =COUNTIFS($F$2:F18,F18,$E$2:E18,E18)>1 -> FALSE | X18: =I18+J18 -> 45 | Y18: =IFERROR(J18/(I18+J18),0) -> 0.66666667 | Z18: =TEXT(DATE(L18, M18, N18), "mmm d, yyyy") -> Jan 19, 2023 | AA18: =LEFT(Z18,3) -> Jan
... A733: =Raw_Data!A733 -> 732 | B733: =Raw_Data!B733 -> 736 | C733: =Raw_Data!C733 -> Organizing a virtual talent show during challenging times, bringing smiles to classmates' faces! | D733: =Raw_Data!D733 -> Happy | E733: =Raw_Data!E733 -> 44150.635 | F733: =Raw_Data!F733 -> VirtualTalentShowSuccessHighSchool | G733: =Raw_Data!G733 -> Instagram | H733: =Raw_Data!H733 -> #VirtualEntertainment #HighSchoolPositivity | ... O733: =Raw_Data!O733 -> 15 | P733: =TRIM(CLEAN(C733)) -> Organizing a virtual talent show during challenging times, bringing smiles to classmates' faces! | Q733: =PROPER(TRIM(CLEAN(D733))) -> Happy | R733: =TRIM(CLEAN(F733)) -> VirtualTalentShowSuccessHighSchool | S733: =TRIM(CLEAN(G733)) -> Instagram | T733: =SUBSTITUTE(TRIM(CLEAN(H733))," ",",") -> #VirtualEntertainment,#HighSchoolPositivity | U733: =TRIM(CLEAN(K733)) -> USA | V733: =IFERROR(VALUE(E733),E733) -> 44150.635 | W733: =COUNTIFS($F$2:F733,F733,$E$2:E733,E733)>1 -> FALSE | X733: =I733+J733 -> 71 | Y733: =IFERROR(J733/(I733+J733),0) -> 0.66197183 | Z733: =TEXT(DATE(L733, M733, N733), "mmm d, yyyy") -> Nov 15, 2020 | AA733: =LEFT(Z733,3) -> Nov

Sheet L1_Logical
A1: Record_ID | B1: Sentiment | C1: Platform | D1: Likes | E1: Retweets | F1: Engagement | G1: Sentiment Band | H1: Engagement Flag | I1: Engagement Tier | J1: US/UK High Engagement | K1: Priority Platform | L1: Not Negative | M1: Error Check | N1: Blank Check | O1: Likes Numeric | P1: Platform Code | Q1: Platform Family
A2: =Clean_Data!A2 -> 0 | B2: =Clean_Data!Q2 -> Positive | C2: =Clean_Data!S2 -> Twitter | D2: =Clean_Data!J2 -> 30 | E2: =Clean_Data!I2 -> 15 | F2: =Clean_Data!X2 -> 45 | G2: {=_xlfn.IFS(OR(B2="Positive",B2="Joy",B2="Happy",B2="Happiness"),"Favorable",OR(B2="Negative",B2="Sad",B2="Grief",B2="Despair",B2="Hate"),"Unfavorable",TRUE,"Other")} -> Favorable | H2: =IF(F2>=50,"High Engagement","Standard Engagement") -> Standard Engagement | I2: =IF(F2>=100,"Viral",IF(F2>=50,"High",IF(F2>=20,"Medium","Low"))) -> Medium | J2: =AND(OR(C2="USA",C2="UK"),F2>=50) -> FALSE | K2: =OR(C2="Twitter",C2="Instagram") -> TRUE | L2: =NOT(G2="Unfavorable") -> TRUE | M2: =ISERROR(1/(D2-D2)) -> TRUE | N2: =ISBLANK(B2) -> FALSE | O2: =ISNUMBER(D2) -> TRUE | P2: =CHOOSE(MATCH(C2,{"Twitter","Instagram","Facebook"},0),"TW","IG","FB") -> TW | Q2: {=_xlfn.SWITCH(C2,"Twitter","Microblog","Instagram","Visual Social","Facebook","Social Network","Other")} -> Microblog
A3: =Clean_Data!A3 -> 1 | B3: =Clean_Data!Q3 -> Negative | C3: =Clean_Data!S3 -> Twitter | D3: =Clean_Data!J3 -> 10 | E3: =Clean_Data!I3 -> 5 | F3: =Clean_Data!X3 -> 15 | G3: {=_xlfn.IFS(OR(B3="Positive",B3="Joy",B3="Happy",B3="Happiness"),"Favorable",OR(B3="Negative",B3="Sad",B3="Grief",B3="Despair",B3="Hate"),"Unfavorable",TRUE,"Other")} -> Unfavorable | H3: =IF(F3>=50,"High Engagement","Standard Engagement") -> Standard Engagement | I3: =IF(F3>=100,"Viral",IF(F3>=50,"High",IF(F3>=20,"Medium","Low"))) -> Low | J3: =AND(OR(C3="USA",C3="UK"),F3>=50) -> FALSE | K3: =OR(C3="Twitter",C3="Instagram") -> TRUE | L3: =NOT(G3="Unfavorable") -> FALSE | M3: =ISERROR(1/(D3-D3)) -> TRUE | N3: =ISBLANK(B3) -> FALSE | O3: =ISNUMBER(D3) -> TRUE | P3: =CHOOSE(MATCH(C3,{"Twitter","Instagram","Facebook"},0),"TW","IG","FB") -> TW | Q3: {=_xlfn.SWITCH(C3,"Twitter","Microblog","Instagram","Visual Social","Facebook","Social Network","Other")} -> Microblog
A4: =Clean_Data!A4 -> 2 | B4: =Clean_Data!Q4 -> Positive | C4: =Clean_Data!S4 -> Instagram | D4: =Clean_Data!J4 -> 40 | E4: =Clean_Data!I4 -> 20 | F4: =Clean_Data!X4 -> 60 | G4: {=_xlfn.IFS(OR(B4="Positive",B4="Joy",B4="Happy",B4="Happiness"),"Favorable",OR(B4="Negative",B4="Sad",B4="Grief",B4="Despair",B4="Hate"),"Unfavorable",TRUE,"Other")} -> Favorable | H4: =IF(F4>=50,"High Engagement","Standard Engagement") -> High Engagement | I4: =IF(F4>=100,"Viral",IF(F4>=50,"High",IF(F4>=20,"Medium","Low"))) -> High | J4: =AND(OR(C4="USA",C4="UK"),F4>=50) -> FALSE | K4: =OR(C4="Twitter",C4="Instagram") -> TRUE | L4: =NOT(G4="Unfavorable") -> TRUE | M4: =ISERROR(1/(D4-D4)) -> TRUE | N4: =ISBLANK(B4) -> FALSE | O4: =ISNUMBER(D4) -> TRUE | P4: =CHOOSE(MATCH(C4,{"Twitter","Instagram","Facebook"},0),"TW","IG","FB") -> IG | Q4: {=_xlfn.SWITCH(C4,"Twitter","Microblog","Instagram","Visual Social","Facebook","Social Network","Other")} -> Visual Social
A5: =Clean_Data!A5 -> 3 | B5: =Clean_Data!Q5 -> Positive | C5: =Clean_Data!S5 -> Facebook | D5: =Clean_Data!J5 -> 15 | E5: =Clean_Data!I5 -> 8 | F5: =Clean_Data!X5 -> 23 | G5: {=_xlfn.IFS(OR(B5="Positive",B5="Joy",B5="Happy",B5="Happiness"),"Favorable",OR(B5="Negative",B5="Sad",B5="Grief",B5="Despair",B5="Hate"),"Unfavorable",TRUE,"Other")} -> Favorable | H5: =IF(F5>=50,"High Engagement","Standard Engagement") -> Standard Engagement | I5: =IF(F5>=100,"Viral",IF(F5>=50,"High",IF(F5>=20,"Medium","Low"))) -> Medium | J5: =AND(OR(C5="USA",C5="UK"),F5>=50) -> FALSE | K5: =OR(C5="Twitter",C5="Instagram") -> FALSE | L5: =NOT(G5="Unfavorable") -> TRUE | M5: =ISERROR(1/(D5-D5)) -> TRUE | N5: =ISBLANK(B5) -> FALSE | O5: =ISNUMBER(D5) -> TRUE | P5: =CHOOSE(MATCH(C5,{"Twitter","Instagram","Facebook"},0),"TW","IG","FB") -> FB | Q5: {=_xlfn.SWITCH(C5,"Twitter","Microblog","Instagram","Visual Social","Facebook","Social Network","Other")} -> Social Network
A6: =Clean_Data!A6 -> 4 | B6: =Clean_Data!Q6 -> Neutral | C6: =Clean_Data!S6 -> Instagram | D6: =Clean_Data!J6 -> 25 | E6: =Clean_Data!I6 -> 12 | F6: =Clean_Data!X6 -> 37 | G6: {=_xlfn.IFS(OR(B6="Positive",B6="Joy",B6="Happy",B6="Happiness"),"Favorable",OR(B6="Negative",B6="Sad",B6="Grief",B6="Despair",B6="Hate"),"Unfavorable",TRUE,"Other")} -> Other | H6: =IF(F6>=50,"High Engagement","Standard Engagement") -> Standard Engagement | I6: =IF(F6>=100,"Viral",IF(F6>=50,"High",IF(F6>=20,"Medium","Low"))) -> Medium | J6: =AND(OR(C6="USA",C6="UK"),F6>=50) -> FALSE | K6: =OR(C6="Twitter",C6="Instagram") -> TRUE | L6: =NOT(G6="Unfavorable") -> TRUE | M6: =ISERROR(1/(D6-D6)) -> TRUE | N6: =ISBLANK(B6) -> FALSE | O6: =ISNUMBER(D6) -> TRUE | P6: =CHOOSE(MATCH(C6,{"Twitter","Instagram","Facebook"},0),"TW","IG","FB") -> IG | Q6: {=_xlfn.SWITCH(C6,"Twitter","Microblog","Instagram","Visual Social","Facebook","Social Network","Other")} -> Visual Social
A7: =Clean_Data!A7 -> 5 | B7: =Clean_Data!Q7 -> Positive | C7: =Clean_Data!S7 -> Twitter | D7: =Clean_Data!J7 -> 50 | E7: =Clean_Data!I7 -> 25 | F7: =Clean_Data!X7 -> 75 | G7: {=_xlfn.IFS(OR(B7="Positive",B7="Joy",B7="Happy",B7="Happiness"),"Favorable",OR(B7="Negative",B7="Sad",B7="Grief",B7="Despair",B7="Hate"),"Unfavorable",TRUE,"Other")} -> Favorable | H7: =IF(F7>=50,"High Engagement","Standard Engagement") -> High Engagement | I7: =IF(F7>=100,"Viral",IF(F7>=50,"High",IF(F7>=20,"Medium","Low"))) -> High | J7: =AND(OR(C7="USA",C7="UK"),F7>=50) -> FALSE | K7: =OR(C7="Twitter",C7="Instagram") -> TRUE | L7: =NOT(G7="Unfavorable") -> TRUE | M7: =ISERROR(1/(D7-D7)) -> TRUE | N7: =ISBLANK(B7) -> FALSE | O7: =ISNUMBER(D7) -> TRUE | P7: =CHOOSE(MATCH(C7,{"Twitter","Instagram","Facebook"},0),"TW","IG","FB") -> TW | Q7: {=_xlfn.SWITCH(C7,"Twitter","Microblog","Instagram","Visual Social","Facebook","Social Network","Other")} -> Microblog
A8: =Clean_Data!A8 -> 6 | B8: =Clean_Data!Q8 -> Positive | C8: =Clean_Data!S8 -> Facebook | D8: =Clean_Data!J8 -> 20 | E8: =Clean_Data!I8 -> 10 | F8: =Clean_Data!X8 -> 30 | G8: {=_xlfn.IFS(OR(B8="Positive",B8="Joy",B8="Happy",B8="Happiness"),"Favorable",OR(B8="Negative",B8="Sad",B8="Grief",B8="Despair",B8="Hate"),"Unfavorable",TRUE,"Other")} -> Favorable | H8: =IF(F8>=50,"High Engagement","Standard Engagement") -> Standard Engagement | I8: =IF(F8>=100,"Viral",IF(F8>=50,"High",IF(F8>=20,"Medium","Low"))) -> Medium | J8: =AND(OR(C8="USA",C8="UK"),F8>=50) -> FALSE | K8: =OR(C8="Twitter",C8="Instagram") -> FALSE | L8: =NOT(G8="Unfavorable") -> TRUE | M8: =ISERROR(1/(D8-D8)) -> TRUE | N8: =ISBLANK(B8) -> FALSE | O8: =ISNUMBER(D8) -> TRUE | P8: =CHOOSE(MATCH(C8,{"Twitter","Instagram","Facebook"},0),"TW","IG","FB") -> FB | Q8: {=_xlfn.SWITCH(C8,"Twitter","Microblog","Instagram","Visual Social","Facebook","Social Network","Other")} -> Social Network
A9: =Clean_Data!A9 -> 7 | B9: =Clean_Data!Q9 -> Positive | C9: =Clean_Data!S9 -> Instagram | D9: =Clean_Data!J9 -> 30 | E9: =Clean_Data!I9 -> 15 | F9: =Clean_Data!X9 -> 45 | G9: {=_xlfn.IFS(OR(B9="Positive",B9="Joy",B9="Happy",B9="Happiness"),"Favorable",OR(B9="Negative",B9="Sad",B9="Grief",B9="Despair",B9="Hate"),"Unfavorable",TRUE,"Other")} -> Favorable | H9: =IF(F9>=50,"High Engagement","Standard Engagement") -> Standard Engagement | I9: =IF(F9>=100,"Viral",IF(F9>=50,"High",IF(F9>=20,"Medium","Low"))) -> Medium | J9: =AND(OR(C9="USA",C9="UK"),F9>=50) -> FALSE | K9: =OR(C9="Twitter",C9="Instagram") -> TRUE | L9: =NOT(G9="Unfavorable") -> TRUE | M9: =ISERROR(1/(D9-D9)) -> TRUE | N9: =ISBLANK(B9) -> FALSE | O9: =ISNUMBER(D9) -> TRUE | P9: =CHOOSE(MATCH(C9,{"Twitter","Instagram","Facebook"},0),"TW","IG","FB") -> IG | Q9: {=_xlfn.SWITCH(C9,"Twitter","Microblog","Instagram","Visual Social","Facebook","Social Network","Other")} -> Visual Social
A10: =Clean_Data!A10 -> 8 | B10: =Clean_Data!Q10 -> Negative | C10: =Clean_Data!S10 -> Twitter | D10: =Clean_Data!J10 -> 60 | E10: =Clean_Data!I10 -> 30 | F10: =Clean_Data!X10 -> 90 | G10: {=_xlfn.IFS(OR(B10="Positive",B10="Joy",B10="Happy",B10="Happiness"),"Favorable",OR(B10="Negative",B10="Sad",B10="Grief",B10="Despair",B10="Hate"),"Unfavorable",TRUE,"Other")} -> Unfavorable | H10: =IF(F10>=50,"High Engagement","Standard Engagement") -> High Engagement | I10: =IF(F10>=100,"Viral",IF(F10>=50,"High",IF(F10>=20,"Medium","Low"))) -> High | J10: =AND(OR(C10="USA",C10="UK"),F10>=50) -> FALSE | K10: =OR(C10="Twitter",C10="Instagram") -> TRUE | L10: =NOT(G10="Unfavorable") -> FALSE | M10: =ISERROR(1/(D10-D10)) -> TRUE | N10: =ISBLANK(B10) -> FALSE | O10: =ISNUMBER(D10) -> TRUE | P10: =CHOOSE(MATCH(C10,{"Twitter","Instagram","Facebook"},0),"TW","IG","FB") -> TW | Q10: {=_xlfn.SWITCH(C10,"Twitter","Microblog","Instagram","Visual Social","Facebook","Social Network","Other")} -> Microblog
A11: =Clean_Data!A11 -> 9 | B11: =Clean_Data!Q11 -> Neutral | C11: =Clean_Data!S11 -> Facebook | D11: =Clean_Data!J11 -> 35 | E11: =Clean_Data!I11 -> 18 | F11: =Clean_Data!X11 -> 53 | G11: {=_xlfn.IFS(OR(B11="Positive",B11="Joy",B11="Happy",B11="Happiness"),"Favorable",OR(B11="Negative",B11="Sad",B11="Grief",B11="Despair",B11="Hate"),"Unfavorable",TRUE,"Other")} -> Other | H11: =IF(F11>=50,"High Engagement","Standard Engagement") -> High Engagement | I11: =IF(F11>=100,"Viral",IF(F11>=50,"High",IF(F11>=20,"Medium","Low"))) -> High | J11: =AND(OR(C11="USA",C11="UK"),F11>=50) -> FALSE | K11: =OR(C11="Twitter",C11="Instagram") -> FALSE | L11: =NOT(G11="Unfavorable") -> TRUE | M11: =ISERROR(1/(D11-D11)) -> TRUE | N11: =ISBLANK(B11) -> FALSE | O11: =ISNUMBER(D11) -> TRUE | P11: =CHOOSE(MATCH(C11,{"Twitter","Instagram","Facebook"},0),"TW","IG","FB") -> FB | Q11: {=_xlfn.SWITCH(C11,"Twitter","Microblog","Instagram","Visual Social","Facebook","Social Network","Other")} -> Social Network
A12: =Clean_Data!A12 -> 10 | B12: =Clean_Data!Q12 -> Positive | C12: =Clean_Data!S12 -> Instagram | D12: =Clean_Data!J12 -> 45 | E12: =Clean_Data!I12 -> 22 | F12: =Clean_Data!X12 -> 67 | G12: {=_xlfn.IFS(OR(B12="Positive",B12="Joy",B12="Happy",B12="Happiness"),"Favorable",OR(B12="Negative",B12="Sad",B12="Grief",B12="Despair",B12="Hate"),"Unfavorable",TRUE,"Other")} -> Favorable | H12: =IF(F12>=50,"High Engagement","Standard Engagement") -> High Engagement | I12: =IF(F12>=100,"Viral",IF(F12>=50,"High",IF(F12>=20,"Medium","Low"))) -> High | J12: =AND(OR(C12="USA",C12="UK"),F12>=50) -> FALSE | K12: =OR(C12="Twitter",C12="Instagram") -> TRUE | L12: =NOT(G12="Unfavorable") -> TRUE | M12: =ISERROR(1/(D12-D12)) -> TRUE | N12: =ISBLANK(B12) -> FALSE | O12: =ISNUMBER(D12) -> TRUE | P12: =CHOOSE(MATCH(C12,{"Twitter","Instagram","Facebook"},0),"TW","IG","FB") -> IG | Q12: {=_xlfn.SWITCH(C12,"Twitter","Microblog","Instagram","Visual Social","Facebook","Social Network","Other")} -> Visual Social
A13: =Clean_Data!A13 -> 11 | B13: =Clean_Data!Q13 -> Negative | C13: =Clean_Data!S13 -> Twitter | D13: =Clean_Data!J13 -> 15 | E13: =Clean_Data!I13 -> 7 | F13: =Clean_Data!X13 -> 22 | G13: {=_xlfn.IFS(OR(B13="Positive",B13="Joy",B13="Happy",B13="Happiness"),"Favorable",OR(B13="Negative",B13="Sad",B13="Grief",B13="Despair",B13="Hate"),"Unfavorable",TRUE,"Other")} -> Unfavorable | H13: =IF(F13>=50,"High Engagement","Standard Engagement") -> Standard Engagement | I13: =IF(F13>=100,"Viral",IF(F13>=50,"High",IF(F13>=20,"Medium","Low"))) -> Medium | J13: =AND(OR(C13="USA",C13="UK"),F13>=50) -> FALSE | K13: =OR(C13="Twitter",C13="Instagram") -> TRUE | L13: =NOT(G13="Unfavorable") -> FALSE | M13: =ISERROR(1/(D13-D13)) -> TRUE | N13: =ISBLANK(B13) -> FALSE | O13: =ISNUMBER(D13) -> TRUE | P13: =CHOOSE(MATCH(C13,{"Twitter","Instagram","Facebook"},0),"TW","IG","FB") -> TW | Q13: {=_xlfn.SWITCH(C13,"Twitter","Microblog","Instagram","Visual Social","Facebook","Social Network","Other")} -> Microblog
... A733: =Clean_Data!A733 -> 732 | B733: =Clean_Data!Q733 -> Happy | C733: =Clean_Data!S733 -> Instagram | D733: =Clean_Data!J733 -> 47 | E733: =Clean_Data!I733 -> 24 | F733: =Clean_Data!X733 -> 71 | G733: {=_xlfn.IFS(OR(B733="Positive",B733="Joy",B733="Happy",B733="Happiness"),"Favorable",OR(B733="Negative",B733="Sad",B733="Grief",B733="Despair",B733="Hate"),"Unfavorable",TRUE,"Other")} -> Favorable | H733: =IF(F733>=50,"High Engagement","Standard Engagement") -> High Engagement | I733: =IF(F733>=100,"Viral",IF(F733>=50,"High",IF(F733>=20,"Medium","Low"))) -> High | J733: =AND(OR(C733="USA",C733="UK"),F733>=50) -> FALSE | K733: =OR(C733="Twitter",C733="Instagram") -> TRUE | L733: =NOT(G733="Unfavorable") -> TRUE | M733: =ISERROR(1/(D733-D733)) -> TRUE | N733: =ISBLANK(B733) -> FALSE | O733: =ISNUMBER(D733) -> TRUE | P733: =CHOOSE(MATCH(C733,{"Twitter","Instagram","Facebook"},0),"TW","IG","FB") -> IG | Q733: {=_xlfn.SWITCH(C733,"Twitter","Microblog","Instagram","Visual Social","Facebook","Social Network","Other")} -> Visual Social

Sheet L1_Lookups
A3: Platform | B3: Code | C3: Family | D3: Target Likes
A4: Twitter | B4: TW | C4: Microblog | D4: 40 | G4: Twitter | H4: Insatgram | I4: Facebook
A5: Instagram | B5: IG | C5: Visual Social | D5: 45 | G5: 40 | H5: 45 | I5: 35
A6: Facebook | B6: FB | C6: Social Network | D6: 35
B8: =VLOOKUP("Instagram",$A$4:$D$6,3,FALSE) -> Visual Social
B9: =HLOOKUP("Facebook",$G$4:$I$5,2,FALSE) -> 35
B10: =_xlfn.XLOOKUP("Twitter",$A$4:$A$6,$B$4:$B$6,"Not found") -> TW
B11: =INDEX($C$4:$C$6,MATCH("Facebook",$A$4:$A$6,0)) -> Social Network
B12: {=INDIRECT("'Clean_Data'!Q2")} -> Positive
B13: =SUM(OFFSET($D$4,0,0,3,1)) -> 120

Sheet L1_Arrays
B1: {=TRANSPOSE(_xlfn._xlws.SORT(_xlfn.UNIQUE(Clean_Data!S2:S733)))} -> Facebook | C1: Instagram | D1: Twitter
B2: {=SUMPRODUCT((Clean_Data!S2:S733="Facebook")*Clean_Data!J2:J733)} -> 9672 | C2: {=SUMPRODUCT((Clean_Data!S2:S733="Instagram")*Clean_Data!J2:J733)} -> 11633 | D2: {=SUMPRODUCT((Clean_Data!S2:S733="Twitter")*Clean_Data!J2:J733)/SUMPRODUCT(--(Clean_Data!S2:S733="Twitter"))} -> 41.559671
A4: {=_xlfn._xlws.SORT(_xlfn.UNIQUE(Clean_Data!S2:S733))} -> Facebook | B4: {=_xlfn._xlws.FILTER(Clean_Data!A2:Y733,Clean_Data!X2:X733>=50,"No matching records")} -> 2 | C4: 2 | D4: Just finished an amazing workout! ðŸ’ª | E4: Positive | F4: 44941.656 | G4: FitnessFan | H4: Instagram | I4: #Fitness #Workout | J4: 20 | K4: 40 | L4: USA | M4: 2023 | N4: 1 | O4: 15 | P4: 15 | Q4: Just finished an amazing workout! ðŸ’ª | R4: Positive | S4: FitnessFan | T4: Instagram | U4: #Fitness,#Workout | V4: USA | W4: 44941.656 | X4: FALSE | Y4: 60 | Z4: 0.66666667
A5: Instagram | B5: 5 | C5: 5 | D5: Feeling grateful for the little things in life. | E5: Positive | F5: 44942.382 | G5: GratitudeNow | H5: Twitter | I5: #Gratitude #PositiveVibes | J5: 25 | K5: 50 | L5: India | M5: 2023 | N5: 1 | O5: 16 | P5: 9 | Q5: Feeling grateful for the little things in life. | R5: Positive | S5: GratitudeNow | T5: Twitter | U5: #Gratitude,#PositiveVibes | V5: India | W5: 44942.382 | X5: FALSE | Y5: 75 | Z5: 0.66666667
A6: Twitter | B6: 8 | C6: 8 | D6: Political discussions heating up on the timeline. | E6: Negative | F6: 44943.333 | G6: DebateTalk | H6: Twitter | I6: #Politics #Debate | J6: 30 | K6: 60 | L6: USA | M6: 2023 | N6: 1 | O6: 17 | P6: 8 | Q6: Political discussions heating up on the timeline. | R6: Negative | S6: DebateTalk | T6: Twitter | U6: #Politics,#Debate | V6: USA | W6: 44943.333 | X6: FALSE | Y6: 90 | Z6: 0.66666667
B7: 9 | C7: 9 | D7: Missing summer vibes and beach days. | E7: Neutral | F7: 44943.514 | G7: BeachLover | H7: Facebook | I7: #Summer #BeachDays | J7: 18 | K7: 35 | L7: Australia | M7: 2023 | N7: 1 | O7: 17 | P7: 12 | Q7: Missing summer vibes and beach days. | R7: Neutral | S7: BeachLover | T7: Facebook | U7: #Summer,#BeachDays | V7: Australia | W7: 44943.514 | X7: FALSE | Y7: 53 | Z7: 0.66037736
A8: {=_xlfn.SEQUENCE(10,1,1,1)} -> 1 | B8: 10 | C8: 10 | D8: Just published a new blog post. Check it out! | E8: Positive | F8: 44943.635 | G8: BloggerX | H8: Instagram | I8: #Blogging #NewPost | J8: 22 | K8: 45 | L8: USA | M8: 2023 | N8: 1 | O8: 17 | P8: 15 | Q8: Just published a new blog post. Check it out! | R8: Positive | S8: BloggerX | T8: Instagram | U8: #Blogging,#NewPost | V8: USA | W8: 44943.635 | X8: FALSE | Y8: 67 | Z8: 0.67164179
A9: 2 | B9: 13 | C9: 13 | D9: New year, new fitness goals! ðŸ’ª | E9: Positive | F9: 44944.75 | G9: FitJourney | H9: Instagram | I9: #NewYear #FitnessGoals | J9: 28 | K9: 55 | L9: USA | M9: 2023 | N9: 1 | O9: 18 | P9: 18 | Q9: New year, new fitness goals! ðŸ’ª | R9: Positive | S9: FitJourney | T9: Instagram | U9: #NewYear,#FitnessGoals | V9: USA | W9: 44944.75 | X9: FALSE | Y9: 83 | Z9: 0.6626506
A10: 3 | B10: 15 | C10: 15 | D10: Reflecting on the past and looking ahead. | E10: Positive | F10: 44945.556 | G10: Reflections | H10: Facebook | I10: #Reflection #Future | J10: 20 | K10: 40 | L10: USA | M10: 2023 | N10: 1 | O10: 19 | P10: 13 | Q10: Reflecting on the past and looking ahead. | R10: Positive | S10: Reflections | T10: Facebook | U10: #Reflection,#Future | V10: USA | W10: 44945.556 | X10: FALSE | Y10: 60 | Z10: 0.66666667
A11: 4 | B11: 17 | C11: 17 | D11: Late-night gaming session with friends. | E11: Positive | F11: 44946.003 | G11: GamerX | H11: Twitter | I11: #Gaming #LateNight | J11: 18 | K11: 35 | L11: UK | M11: 2023 | N11: 1 | O11: 20 | P11: 0 | Q11: Late-night gaming session with friends. | R11: Positive | S11: GamerX | T11: Twitter | U11: #Gaming,#LateNight | V11: UK | W11: 44946.003 | X11: FALSE | Y11: 53 | Z11: 0.66037736
A12: 5 | B12: 18 | C12: 18 | D12: Attending a virtual conference on AI. | E12: Neutral | F12: 44946.479 | G12: TechConference | H12: Facebook | I12: #AI #TechConference | J12: 25 | K12: 50 | L12: USA | M12: 2023 | N12: 1 | O12: 20 | P12: 11 | Q12: Attending a virtual conference on AI. | R12: Neutral | S12: TechConference | T12: Facebook | U12: #AI,#TechConference | V12: USA | W12: 44946.479 | X12: FALSE | Y12: 75 | Z12: 0.66666667
A13: 6 | B13: 20 | C13: 20 | D13: Sipping coffee and enjoying a good book. | E13: Positive | F13: 44947.361 | G13: Bookworm | H13: Twitter | I13: #Reading #CoffeeTime | J13: 22 | K13: 45 | L13: India | M13: 2023 | N13: 1 | O13: 21 | P13: 8 | Q13: Sipping coffee and enjoying a good book. | R13: Positive | S13: Bookworm | T13: Twitter | U13: #Reading,#CoffeeTime | V13: India | W13: 44947.361 | X13: FALSE | Y13: 67 | Z13: 0.67164179
A14: 7 | B14: 22 | C14: 22 | D14: Productive day ticking off my to-do list. | E14: Positive | F14: 44947.698 | G14: ProductivityPro | H14: Instagram | I14: #Productivity #WorkFromHome | J14: 30 | K14: 60 | L14: USA | M14: 2023 | N14: 1 | O14: 21 | P14: 16 | Q14: Productive day ticking off my to-do list. | R14: Positive | S14: ProductivityPro | T14: Instagram | U14: #Productivity,#WorkFromHome | V14: USA | W14: 44947.698 | X14: FALSE | Y14: 90 | Z14: 0.66666667
A15: 8 | B15: 23 | C15: 23 | D15: Just finished a challenging workout routine. | E15: Positive | F15: 44948.385 | G15: FitnessWarrior | H15: Twitter | I15: #Fitness #ChallengeAccepted | J15: 20 | K15: 40 | L15: UK | M15: 2023 | N15: 1 | O15: 22 | P15: 9 | Q15: Just finished a challenging workout routine. | R15: Positive | S15: FitnessWarrior | T15: Twitter | U15: #Fitness,#ChallengeAccepted | V15: UK | W15: 44948.385 | X15: FALSE | Y15: 60 | Z15: 0.66666667
A16: 9 | B16: 27 | C16: 28 | D16: Learning a new language for personal growth. | E16: Positive | F16: 44949.681 | G16: LanguageLearner | H16: Facebook | I16: #LanguageLearning #PersonalGrowth | J16: 25 | K16: 50 | L16: India | M16: 2023 | N16: 1 | O16: 23 | P16: 16 | Q16: Learning a new language for personal growth. | R16: Positive | S16: LanguageLearner | T16: Facebook | U16: #LanguageLearning,#PersonalGrowth | V16: India | W16: 44949.681 | X16: FALSE | Y16: 75 | Z16: 0.66666667
A17: 10 | B17: 29 | C17: 30 | D17: Reflecting on the importance of mental health. | E17: Positive | F17: 44950.479 | G17: MentalHealthMatters | H17: Twitter | I17: #MentalHealth #SelfCare | J17: 22 | K17: 45 | L17: USA | M17: 2023 | N17: 1 | O17: 24 | P17: 11 | Q17: Reflecting on the importance of mental health. | R17: Positive | S17: MentalHealthMatters | T17: Twitter | U17: #MentalHealth,#SelfCare | V17: USA | W17: 44950.479 | X17: FALSE | Y17: 67 | Z17: 0.67164179
B18: 31 | C18: 32 | D18: Weekend road trip to explore scenic views. | E18: Positive | F18: 44950.729 | G18: RoadTripper | H18: Instagram | I18: #RoadTrip #ScenicViews | J18: 18 | K18: 35 | L18: UK | M18: 2023 | N18: 1 | O18: 24 | P18: 17 | Q18: Weekend road trip to explore scenic views. | R18: Positive | S18: RoadTripper | T18: Instagram | U18: #RoadTrip,#ScenicViews | V18: UK | W18: 44950.729 | X18: FALSE | Y18: 53 | Z18: 0.66037736
B19: 33 | C19: 34 | D19: Coding a new project with enthusiasm. | E19: Positive | F19: 44951.552 | G19: CodeEnthusiast | H19: Facebook | I19: #Coding #Enthusiasm | J19: 30 | K19: 60 | L19: USA | M19: 2023 | N19: 1 | O19: 25 | P19: 13 | Q19: Coding a new project with enthusiasm. | R19: Positive | S19: CodeEnthusiast | T19: Facebook | U19: #Coding,#Enthusiasm | V19: USA | W19: 44951.552 | X19: FALSE | Y19: 90 | Z19: 0.66666667
B20: 34 | C20: 35 | D20: Feeling inspired after attending a workshop. | E20: Positive | F20: 44952.406 | G20: WorkshopAttendee | H20: Instagram | I20: #Inspiration #Workshop | J20: 25 | K20: 50 | L20: USA | M20: 2023 | N20: 1 | O20: 26 | P20: 9 | Q20: Feeling inspired after attending a workshop. | R20: Positive | S20: WorkshopAttendee | T20: Instagram | U20: #Inspiration,#Workshop | V20: USA | W20: 44952.406 | X20: FALSE | Y20: 75 | Z20: 0.66666667
B21: 36 | C21: 37 | D21: Quality time with family this weekend. | E21: Positive | F21: 44952.736 | G21: FamilyTime | H21: Facebook | I21: #FamilyTime #Weekend | J21: 22 | K21: 45 | L21: UK | M21: 2023 | N21: 1 | O21: 26 | P21: 17 | Q21: Quality time with family this weekend. | R21: Positive | S21: FamilyTime | T21: Facebook | U21: #FamilyTime,#Weekend | V21: UK | W21: 44952.736 | X21: FALSE | Y21: 67 | Z21: 0.67164179
B22: 37 | C22: 38 | D22: Attending a live music concert tonight. | E22: Positive | F22: 44953.833 | G22: MusicLover | H22: Instagram | I22: #Music #ConcertNight | J22: 18 | K22: 35 | L22: USA | M22: 2023 | N22: 1 | O22: 27 | P22: 20 | Q22: Attending a live music concert tonight. | R22: Positive | S22: MusicLover | T22: Instagram | U22: #Music,#ConcertNight | V22: USA | W22: 44953.833 | X22: FALSE | Y22: 53 | Z22: 0.66037736
B23: 40 | C23: 41 | D23: Excited about the upcoming gaming tournament. | E23: Positive | F23: 44954.375 | G23: GamingEnthusiast | H23: Instagram | I23: #Gaming #Tournament | J23: 30 | K23: 60 | L23: USA | M23: 2023 | N23: 1 | O23: 28 | P23: 9 | Q23: Excited about the upcoming gaming tournament. | R23: Positive | S23: GamingEnthusiast | T23: Instagram | U23: #Gaming,#Tournament | V23: USA | W23: 44954.375 | X23: FALSE | Y23: 90 | Z23: 0.66666667
B24: 41 | C24: 42 | D24: Planning a garden makeover for spring. | E24: Positive | F24: 44954.615 | G24: GardenPlanner | H24: Twitter | I24: #Gardening #Spring | J24: 25 | K24: 50 | L24: USA | M24: 2023 | N24: 1 | O24: 28 | P24: 14 | Q24: Planning a garden makeover for spring. | R24: Positive | S24: GardenPlanner | T24: Twitter | U24: #Gardening,#Spring | V24: USA | W24: 44954.615 | X24: FALSE | Y24: 75 | Z24: 0.66666667
B25: 43 | C25: 44 | D25: Feeling accomplished after a productive day. | E25: Positive | F25: 44955.708 | G25: ProductivityWin | H25: Instagram | I25: #Accomplished #Success | J25: 22 | K25: 45 | L25: India | M25: 2023 | N25: 1 | O25: 29 | P25: 17 | Q25: Feeling accomplished after a productive day. | R25: Positive | S25: ProductivityWin | T25: Instagram | U25: #Accomplished,#Success | V25: India | W25: 44955.708 | X25: FALSE | Y25: 67 | Z25: 0.67164179
B26: 44 | C26: 45 | D26: A cozy evening with a good movie. | E26: Positive | F26: 44955.847 | G26: MovieNight | H26: Twitter | I26: #CozyNight #MovieTime | J26: 18 | K26: 35 | L26: Canada | M26: 2023 | N26: 1 | O26: 29 | P26: 20 | Q26: A cozy evening with a good movie. | R26: Positive | S26: MovieNight | T26: Twitter | U26: #CozyNight,#MovieTime | V26: Canada | W26: 44955.847 | X26: FALSE | Y26: 53 | Z26: 0.66037736
B27: 47 | C27: 48 | D27: Attending a virtual reality meetup. | E27: Positive | F27: 44956.771 | G27: VRMeetup | H27: Twitter | I27: #VRMeetup #VirtualReality | J27: 28 | K27: 55 | L27: India | M27: 2023 | N27: 1 | O27: 30 | P27: 18 | Q27: Attending a virtual reality meetup. | R27: Positive | S27: VRMeetup | T27: Twitter | U27: #VRMeetup,#VirtualReality | V27: India | W27: 44956.771 | X27: FALSE | Y27: 83 | Z27: 0.6626506
B28: 49 | C28: 50 | D28: Cooking a special dinner for loved ones. | E28: Positive | F28: 44957.792 | G28: ChefAtHome | H28: Instagram | I28: #Cooking #SpecialDinner | J28: 20 | K28: 40 | L28: USA | M28: 2023 | N28: 1 | O28: 31 | P28: 19 | Q28: Cooking a special dinner for loved ones. | R28: Positive | S28: ChefAtHome | T28: Instagram | U28: #Cooking,#SpecialDinner | V28: USA | W28: 44957.792 | X28: FALSE | Y28: 60 | Z28: 0.66666667
B29: 51 | C29: 52 | D29: Starting a new fitness challenge tomorrow! ðŸ’ª | E29: Positive | F29: 44958.333 | G29: FitnessChallenge | H29: Facebook | I29: #FitnessChallenge #NewBeginnings | J29: 22 | K29: 45 | L29: UK | M29: 2023 | N29: 2 | O29: 1 | P29: 8 | Q29: Starting a new fitness challenge tomorrow! ðŸ’ª | R29: Positive | S29: FitnessChallenge | T29: Facebook | U29: #FitnessChallenge,#NewBeginnings | V29: UK | W29: 44958.333 | X29: FALSE | Y29: 67 | Z29: 0.67164179
... B557: 732 | C557: 736 | D557: Organizing a virtual talent show during challenging times, bringing smiles to classmates' faces! | E557: Happy | F557: 44150.635 | G557: VirtualTalentShowSuccessHighSchool | H557: Instagram | I557: #VirtualEntertainment #HighSchoolPositivity | J557: 24 | K557: 47 | L557: USA | M557: 2020 | N557: 11 | O557: 15 | P557: 15 | Q557: Organizing a virtual talent show during challenging times, bringing smiles to classmates' faces! | R557: Happy | S557: VirtualTalentShowSuccessHighSchool | T557: Instagram | U557: #VirtualEntertainment,#HighSchoolPositivity | V557: USA | W557: 44150.635 | X557: FALSE | Y557: 71 | Z557: 0.66197183

Sheet L2_Statistics
A1: Likes Statistics | D1: Platform | F1: Likes | G1: Retweets
A2: Average Likes | B2: =AVERAGE(Clean_Data!J2:J733) -> 42.901639 | D2: Total Twiter likes | F2: 10099 | G2: 5069
A3: Median Likes | B3: =MEDIAN(Clean_Data!J2:J733) -> 43 | D3: Total Facebook likes | F3: 9672 | G3: 4844
A4: Mode Likes | B4: =_xlfn.MODE.SNGL(Clean_Data!J2:J733) -> 45 | D4: Total Instagram likes | F4: 11633 | G4: 5831
A5: Standard variation | B5: =_xlfn.VAR.S(Clean_Data!J2:J733) -> 198.52383
A6: Standard deviation | B6: =_xlfn.STDEV.S(Clean_Data!J2:J733) -> 14.089848 | D6: Max likes | F6: =MAX(F2:F4) -> 11633
A7: correletion | B7: =CORREL(Clean_Data!J2:J733,Clean_Data!I2:I733) -> 0.99848211
A8: Covariance | B8: =_xlfn.COVARIANCE.S(Clean_Data!J2:J733,Clean_Data!I2:I733) -> 99.341437
A9: Slope | B9: =SLOPE(Clean_Data!J2:J733,Clean_Data!I2:I733) -> 1.9923369
A10: Intercept | B10: =INTERCEPT(Clean_Data!J2:J733,Clean_Data!I2:I733) -> 0.050065081
A11: RSQ | B11: =RSQ(Clean_Data!J2:J733,Clean_Data!I2:I733) -> 0.99696653
A12: T-Test | B12: {=_xlfn.T.TEST(_xlfn._xlws.FILTER(Clean_Data!J2:J733,Clean_Data!S2:S733="Instagram"),_xlfn._xlws.FILTER(Clean_Data!J2:J733,Clean_Data!S2:S733="Twitter"),2,3)} -> 0.006639788

Sheet PivotTable
B4: Row Labels | C4: Sum of Likes | E4: Row Labels | F4: Sum of Likes | G4: Average of Engagement | I4: Row Labels | J4: Sum of Retweets
B5: Facebook | C5: 9672 | E5: Australia | F5: 2926 | G5: 58.533333 | I5: Facebook | J5: 4844
B6: Instagram | C6: 11633 | E6: Facebook | F6: 1056 | G6: 60.923077 | I6: Instagram | J6: 5831
B7: Twitter | C7: 5809 | E7: Instagram | F7: 1003 | G7: 55.777778 | I7: Twitter | J7: 2918
B8: Twitter | C8: 4290 | E8: Twitter | F8: 867 | G8: 59.090909 | I8: Twitter | J8: 2151
B9: Grand Total | C9: 31404 | E9: Austria | F9: 90 | G9: 67 | I9: Grand Total | J9: 15744
E10: Facebook | F10: 90 | G10: 67
E11: Belgium | F11: 140 | G11: 105
E12: Twitter | F12: 140 | G12: 105
E13: Brazil | F13: 900 | G13: 79.294118 | I13: Row Labels | J13: Sum of Likes | L13: Row Labels | M13: Average of Retweets | N13: Average of Likes | O13: Row Labels | P13: Sum of Likes | Q13: Sum of Retweets
E14: Facebook | F14: 290 | G14: 72.5 | I14: Facebook | J14: 9672 | L14: Acceptance | M14: 17.333333 | N14: 35 | O14: Jan | P14: 3157 | Q14: 1577
E15: Instagram | F15: 330 | G15: 82.333333 | I15: Australia | J15: 1056 | L15: Facebook | M15: 15 | N15: 30 | O15: Feb | P15: 3505 | Q15: 1753
E16: Twitter | F16: 280 | G16: 83.8 | I16: Austria | J16: 90 | L16: Twitter | M16: 22 | N16: 45 | O16: Mar | P16: 1875 | Q16: 937
E17: Cambodia | F17: 40 | G17: 60 | I17: Brazil | J17: 290 | L17: Acceptance | M17: 16.8 | N17: 33.6 | O17: Apr | P17: 2175 | Q17: 1087
E18: Instagram | F18: 40 | G18: 60 | I18: Canada | J18: 1760 | L18: Facebook | M18: 16.5 | N18: 33 | O18: May | P18: 1924 | Q18: 963
E19: Canada | F19: 5488 | G19: 61.02963 | I19: Colombia | J19: 55 | L19: Instagram | M19: 16.5 | N19: 33 | O19: Jun | P19: 3358 | Q19: 1683
E20: Facebook | F20: 1760 | G20: 59.977273 | I20: Czech Republic | J20: 70 | L20: Twitter | M20: 18 | N20: 36 | O20: Jul | P20: 3046 | Q20: 1523
E21: Instagram | F21: 1867 | G21: 62.311111 | I21: France | J21: 115 | L21: Accomplishment | M21: 26 | N21: 51.666667 | O21: Aug | P21: 3411 | Q21: 1718
E22: Twitter | F22: 1861 | G22: 60.782609 | I22: Germany | J22: 370 | L22: Facebook | M22: 26 | N22: 51.666667 | O22: Sep | P22: 3182 | Q22: 1606
E23: China | F23: 35 | G23: 53 | I23: Greece | J23: 80 | L23: Admiration | M23: 22 | N23: 45 | O23: Oct | P23: 1995 | Q23: 1006
E24: Twitter | F24: 35 | G24: 53 | I24: India | J24: 746 | L24: Instagram | M24: 22 | N24: 45 | O24: Nov | P24: 2143 | Q24: 1076
E25: Colombia | F25: 55 | G25: 83 | I25: Italy | J25: 220 | L25: Admiration | M25: 20 | N25: 40 | O25: Dec | P25: 1633 | Q25: 815
E26: Facebook | F26: 55 | G26: 83 | I26: Japan | J26: 335 | L26: Twitter | M26: 20 | N26: 40 | O26: Grand Total | P26: 31404 | Q26: 15744
E27: Czech Republic | F27: 70 | G27: 53 | I27: Maldives | J27: 45 | L27: Admiration | M27: 25 | N27: 50
E28: Facebook | F28: 70 | G28: 53 | I28: Netherlands | J28: 145 | L28: Instagram | M28: 25 | N28: 50
E29: Denmark | F29: 80 | G29: 60 | I29: Peru | J29: 55 | L29: Adoration | M29: 22 | N29: 45
E30: Instagram | F30: 80 | G30: 60 | I30: Portugal | J30: 110 | L30: Twitter | M30: 22 | N30: 45
E31: France | F31: 740 | G31: 69.5 | I31: UK | J31: 1613 | L31: Adrenaline | M31: 22 | N31: 45
E32: Facebook | F32: 115 | G32: 86.5 | I32: USA | J32: 2517 | L32: Facebook | M32: 22 | N32: 45
E33: Instagram | F33: 250 | G33: 75.2 | I33: Instagram | J33: 11633 | L33: Adventure | M33: 30.666667 | N33: 61.666667
E34: Twitter | F34: 375 | G34: 62.555556 | I34: Australia | J34: 1003 | L34: Twitter | M34: 28.5 | N34: 57.5
E35: Germany | F35: 675 | G35: 72.428571 | I35: Brazil | J35: 330 | L35: Twitter | M35: 35 | N35: 70
E36: Facebook | F36: 370 | G36: 79.285714 | I36: Cambodia | J36: 40 | L36: Affection | M36: 15 | N36: 30
E37: Instagram | F37: 115 | G37: 57.666667 | I37: Canada | J37: 1867 | L37: Instagram | M37: 15 | N37: 30
E38: Twitter | F38: 190 | G38: 71.5 | I38: Denmark | J38: 80 | L38: Amazement | M38: 30 | N38: 60
... E87: UK | F87: 5827 | G87: 61.244755 | I87: Grand Total | J87: 31404 | L87: Betrayal | M87: 22 | N87: 45
E88: Facebook | F88: 1613 | G88: 57.642857 | L88: Twitter | M88: 22 | N88: 45
E89: Instagram | F89: 2311 | G89: 65.490566 | L89: Bitter | M89: 17 | N89: 33.333333
E90: Twitter | F90: 1903 | G90: 59.708333 | L90: Facebook | M90: 18 | N90: 35
E91: USA | F91: 8358 | G91: 66.765957 | L91: Twitter | M91: 15 | N91: 30
...

Sheet Dashboard
